Workbook

Sheet Instructions
B2: TrikRide — Survey Tally Workbook
B3: A Smart Tricycle Ride and Driver Onboarding System for Talibon Polytechnic College
B4: Transcribed from Mumar_Capstone_Revised_2.docx. Every count and mean on the tally sheets is a formula — type the raw responses and the tallies fill themselves in.
B6: How to use it
B7: 1. | C7: Enter one questionnaire per row on the matching Responses sheet. Passengers, drivers and the administrator each have their own sheet, because they answered different instruments.
B8: 2. | C8: Put a whole number 1 to 5 in each item column — the weight the respondent ticked. Leave a cell blank if they skipped that item; blanks are excluded from that item's mean rather than counted as zero.
B9: 3. | C9: Row 5 of each Responses sheet is a worked example, shaded yellow. Delete that row before you tally — it is outside the formula range, so it will not affect the results either way.
B10: 4. | C10: Read the results on the three Tally sheets. Nothing there needs typing.
B11: 5. | C11: Type the written answers on the Open-Ended sheet, one row per respondent.
B13: Rating scale, as printed on the questionnaire
B14: Weight | C14: Weighted Mean | D14: Response
B15: 5 | C15: 4.21 - 5.00 | D15: Strongly Agree
B16: 4 | C16: 3.41 - 4.20 | D16: Agree
B17: 3 | C17: 2.61 - 3.40 | D17: Neutral
B18: 2 | C18: 1.81 - 2.60 | D18: Disagree
B19: 1 | C19: 1.00 - 1.80 | D19: Strongly Disagree
B21: What is in this workbook
B22: Passenger Responses | C22: Profile + 34 items (Part II, A to F)
B23: Driver Responses | C23: Profile + 20 items (the separate driver instrument)
B24: Admin Responses | C24: Profile + 7 items (Part III)
B25: Tally - Passenger | C25: Counts, weighted mean and interpretation per item
B26: Tally - Driver | C26: The same, for drivers
B27: Tally - Admin | C27: The same, for the administrator
B28: Open-Ended | C28: The written answers, verbatim
B30: One thing to fix before printing
B31: Part II, section B (Usability) lists "The system is easy to learn." twice — as item 1 and again as item 6. It is kept here exactly as printed so the sheet matches the paper, but asking the same question twice pulls that section's mean toward whatever respondents think of that one statement. Replace item 6 on the questionnaire and on the Passenger Responses and Tally - Passenger sheets, or delete it from all three.
B33: Source: Mumar_Capstone_Revised_2.docx, Survey Questionnaire (Parts I to IV) and the driver instrument that follows it.

Sheet Passenger Responses
A1: Passenger Responses
A2: One row per student/passenger respondent. Item columns take a whole number 1-5; the full statement is printed sideways above each one.
I3: The ride booking feature works as expected. | J3: I receive timely notifications about my ride status. | K3: The system accurately matches me with an available driver. | L3: I can view the status of my booking in real time. | M3: The system performs all its intended functions correctly. | N3: The fare displayed is accurate. | O3: Driver information is correctly displayed. | P3: Ride history is properly recorded. | Q3: The system is easy to learn. | R3: The menus are easy to understand. | S3: Icons and buttons are properly labeled. | T3: The interface is visually appealing. | U3: I can complete my tasks without confusion. | V3: The system is easy to learn. | W3: The application loads quickly. | X3: Booking requests are processed immediately. | Y3: Notifications arrive without delay. | Z3: The system performs smoothly. | AA3: The application consumes minimal mobile resources. | AB3: The system recovers properly after connection interruptions. | AC3: I can depend on the system to connect me with a driver when needed. | AD3: The system maintains accurate and up-to-date information. | AE3: The system performs well even during peak hours. | AF3: I trust the system to provide a safe and reliable ride booking experience. | AG3: I feel that my personal information is protected. | AH3: The login process is secure. | AI3: Only authorized users can access their accounts. | AJ3: Driver information is securely stored. | AK3: I trust the system to protect my data. | AL3: I am satisfied with the overall performance of the system. | AM3: I would recommend this system to others. | AN3: I intend to continue using the system. | AO3: The system meets my expectations. | AP3: Overall, I rate the system as effective.
A4: Respondent No. | B4: Name (optional) | C4: Age | D4: Gender | E4: Course | F4: Year Level | G4: Frequency of using tricycles | H4: Average rides per week | I4: A1 | J4: A2 | K4: A3 | L4: A4 | M4: A5 | N4: A6 | O4: A7 | P4: A8 | Q4: B1 | R4: B2 | S4: B3 | T4: B4 | U4: B5 | V4: B6 | W4: C1 | X4: C2 | Y4: C3 | Z4: C4 | AA4: C5 | AB4: D1 | AC4: D2 | AD4: D3 | AE4: D4 | AF4: D5 | AG4: E1 | AH4: E2 | AI4: E3 | AJ4: E4 | AK4: E5 | AL4: F1 | AM4: F2 | AN4: F3 | AO4: F4 | AP4: F5
A5: EXAMPLE - delete | B5: Juan Dela Cruz | C5: 20 | D5: Female | E5: BSIS | F5: 3rd Year | G5: Often | H5: 6-10 | I5: 5 | J5: 4 | K5: 5 | L5: 4 | M5: 5 | N5: 5 | O5: 4 | P5: 5 | Q5: 4 | R5: 5 | S5: 5 | T5: 4 | U5: 5 | V5: 4 | W5: 5 | X5: 5 | Y5: 4 | Z5: 5 | AA5: 4 | AB5: 5 | AC5: 5 | AD5: 4 | AE5: 5 | AF5: 4 | AG5: 5 | AH5: 5 | AI5: 4 | AJ5: 5 | AK5: 4 | AL5: 5 | AM5: 5 | AN5: 4 | AO5: 5 | AP5: 4
A6: 1 | B6: Name (optional) | C6: 18 | D6: Female | E6: BSAIS | F6: 2nd Year | G6: Sometimes | H6: 1 -- 5 | I6: 5 | J6: 4 | K6: 5 | L6: 5 | M6: 5 | N6: 4 | O6: 4 | P6: 4 | Q6: 5 | R6: 5 | S6: 5 | T6: 5 | U6: 5 | V6: 5 | W6: 4 | X6: 4 | Y6: 4 | Z6: 5 | AA6: 5 | AB6: 4 | AC6: 5 | AD6: 4 | AE6: 4 | AF6: 4 | AG6: 5 | AH6: 5 | AI6: 5 | AJ6: 5 | AK6: 5 | AL6: 5 | AM6: 5 | AN6: 5 | AO6: 5 | AP6: 5
A7: 2 | B7: Name (optional) | C7: 20 | D7: Female | E7: BSA | F7: 3rd Year | G7: Sometimes | H7: 11 -- 15 | I7: 4 | J7: 4 | K7: 5 | L7: 5 | M7: 5 | N7: 5 | O7: 5 | P7: 5 | Q7: 4 | R7: 4 | S7: 5 | T7: 5 | U7: 5 | V7: 4 | W7: 4 | X7: 4 | Y7: 3 | Z7: 3 | AA7: 4 | AB7: 5 | AC7: 4 | AD7: 4 | AE7: 4 | AF7: 5 | AG7: 4 | AH7: 4 | AI7: 3 | AJ7: 3 | AK7: 4 | AL7: 5 | AM7: 5 | AN7: 5 | AO7: 5 | AP7: 5
A8: 3 | B8: Name (optional) | C8: 19 | D8: Female | E8: BSAIS | F8: 2nd Year | G8: Sometimes | H8: 1 -- 5 | I8: 5 | J8: 4 | K8: 4 | L8: 4 | M8: 5 | N8: 4 | O8: 4 | P8: 4 | Q8: 4 | R8: 4 | S8: 4 | T8: 4 | U8: 4 | V8: 4 | W8: 4 | X8: 4 | Y8: 4 | Z8: 4 | AA8: 4 | AB8: 4 | AC8: 4 | AD8: 4 | AE8: 4 | AF8: 4 | AG8: 4 | AH8: 4 | AI8: 4 | AJ8: 4 | AK8: 4 | AL8: 5 | AM8: 5 | AN8: 5 | AO8: 5 | AP8: 5
A9: 4 | B9: Name (optional) | C9: 19 | D9: Female | E9: BSAIS | F9: 2nd Year | G9: Often | H9: 1 -- 5 | I9: 4 | J9: 4 | K9: 4 | L9: 4 | M9: 3 | N9: 4 | O9: 4 | P9: 4 | Q9: 4 | R9: 4 | S9: 4 | T9: 4 | U9: 4 | V9: 4 | W9: 5 | X9: 4 | Y9: 4 | Z9: 4 | AA9: 5 | AB9: 4 | AC9: 5 | AD9: 4 | AE9: 4 | AF9: 4 | AG9: 4 | AH9: 5 | AI9: 5 | AJ9: 5 | AK9: 5 | AL9: 4 | AM9: 4 | AN9: 4 | AO9: 5 | AP9: 4
A10: 5 | B10: Name (optional) | C10: 18 | D10: Female | E10: BECED | F10: 2nd Year | G10: Rarely | H10: 1 -- 5 | I10: 4 | J10: 4 | K10: 5 | L10: 4 | M10: 4 | N10: 4 | O10: 4 | P10: 4 | Q10: 4 | R10: 4 | S10: 4 | T10: 4 | U10: 4 | V10: 4 | W10: 4 | X10: 4 | Y10: 4 | Z10: 4 | AA10: 4 | AB10: 4 | AC10: 4 | AD10: 4 | AE10: 4 | AF10: 4 | AG10: 4 | AH10: 4 | AI10: 4 | AJ10: 4 | AK10: 4 | AL10: 4 | AM10: 4 | AN10: 4 | AO10: 4 | AP10: 4
A11: 6 | B11: Name (optional) | C11: 18 | D11: Male | E11: BECED | F11: 1st Year | G11: Rarely | H11: 1 -- 5 | I11: 4 | J11: 4 | K11: 3 | L11: 4 | M11: 4 | N11: 4 | O11: 4 | P11: 4 | Q11: 5 | R11: 4 | S11: 4 | T11: 3 | U11: 4 | V11: 4 | W11: 4 | X11: 4 | Y11: 4 | Z11: 4 | AA11: 4 | AB11: 4 | AC11: 4 | AD11: 4 | AE11: 4 | AF11: 4 | AG11: 4 | AH11: 4 | AI11: 4 | AJ11: 4 | AK11: 4 | AL11: 4 | AM11: 4 | AN11: 4 | AO11: 4 | AP11: 4
A12: 7 | B12: Name (optional) | C12: 19 | D12: Female | E12: BECED | F12: 2nd Year | G12: Every Day | H12: 1 -- 5 | I12: 4 | J12: 4 | K12: 5 | L12: 3 | M12: 4 | N12: 4 | O12: 4 | P12: 4 | Q12: 5 | R12: 5 | S12: 4 | T12: 5 | U12: 5 | V12: 4 | W12: 5 | X12: 4 | Y12: 4 | Z12: 5 | AA12: 5 | AB12: 5 | AC12: 4 | AD12: 5 | AE12: 5 | AF12: 5 | AG12: 4 | AH12: 4 | AI12: 5 | AJ12: 5 | AK12: 4 | AL12: 5 | AM12: 4 | AN12: 4 | AO12: 4 | AP12: 4
A13: 8 | B13: Name (optional) | C13: 21 | D13: Male | E13: BSIS | F13: 3rd Year | G13: Rarely | H13: 1 -- 5 | I13: 4 | J13: 4 | K13: 4 | L13: 4 | M13: 5 | N13: 4 | O13: 4 | P13: 5 | Q13: 5 | R13: 5 | S13: 4 | T13: 5 | U13: 4 | V13: 5 | W13: 5 | X13: 5 | Y13: 4 | Z13: 5 | AA13: 4 | AB13: 5 | AC13: 5 | AD13: 4 | AE13: 5 | AF13: 4 | AG13: 5 | AH13: 5 | AI13: 4 | AJ13: 4 | AK13: 5 | AL13: 5 | AM13: 4 | AN13: 4 | AO13: 5 | AP13: 5
A14: 9 | B14: Name (optional) | C14: 20 | D14: Male | E14: BSIS | F14: 3rd Year | G14: Every Day | H14: 16 - 20 | I14: 4 | J14: 4 | K14: 4 | L14: 3 | M14: 4 | N14: 4 | O14: 4 | P14: 4 | Q14: 4 | R14: 5 | S14: 4 | T14: 4 | U14: 4 | V14: 4 | W14: 4 | X14: 4 | Y14: 4 | Z14: 4 | AA14: 4 | AB14: 4 | AC14: 4 | AD14: 4 | AE14: 4 | AF14: 4 | AG14: 4 | AH14: 4 | AI14: 4 | AJ14: 5 | AK14: 4 | AL14: 4 | AM14: 4 | AN14: 4 | AO14: 4 | AP14: 4
A15: 10 | B15: Name (optional) | C15: 19 | D15: Male | E15: BSIS | F15: 3rd Year | G15: Rarely | H15: 1 -- 5 | I15: 3 | J15: 4 | K15: 4 | L15: 4 | M15: 4 | N15: 5 | O15: 4 | P15: 4 | Q15: 4 | R15: 4 | S15: 4 | T15: 4 | U15: 5 | V15: 4 | W15: 4 | X15: 4 | Y15: 3 | Z15: 4 | AA15: 4 | AB15: 5 | AC15: 5 | AD15: 4 | AE15: 4 | AF15: 5 | AG15: 4 | AH15: 4 | AI15: 5 | AJ15: 4 | AK15: 4 | AL15: 4 | AM15: 4 | AN15: 4 | AO15: 5 | AP15: 5
A16: 11 | B16: Name (optional) | C16: 22 | D16: Male | E16: BSIS | F16: 3rd Year | G16: Sometimes | H16: 1 -- 5 | I16: 4 | J16: 4 | K16: 5 | L16: 4 | M16: 5 | N16: 4 | O16: 4 | P16: 4 | Q16: 4 | R16: 5 | S16: 5 | T16: 4 | U16: 5 | V16: 4 | W16: 4 | X16: 4 | Y16: 4 | Z16: 5 | AA16: 5 | AB16: 5 | AC16: 4 | AD16: 5 | AE16: 4 | AF16: 4 | AG16: 4 | AH16: 5 | AI16: 4 | AJ16: 5 | AK16: 5 | AL16: 4 | AM16: 5 | AN16: 5 | AO16: 4 | AP16: 4
A17: 12 | B17: Name (optional) | C17: 21 | D17: Male | E17: BSIS | F17: 3rd Year | G17: Rarely | H17: 1 -- 5 | I17: 4 | J17: 4 | K17: 5 | L17: 4 | M17: 5 | N17: 4 | O17: 5 | P17: 5 | Q17: 4 | R17: 4 | S17: 4 | T17: 4 | U17: 4 | V17: 4 | W17: 4 | X17: 4 | Y17: 4 | Z17: 4 | AA17: 4 | AB17: 4 | AC17: 4 | AD17: 4 | AE17: 4 | AF17: 4 | AG17: 4 | AH17: 4 | AI17: 4 | AJ17: 4 | AK17: 4 | AL17: 4 | AM17: 4 | AN17: 4 | AO17: 4 | AP17: 4
... A25: 20 | B25: Name (optional) | C25: 19 | D25: Female | E25: BSAIS | F25: 2nd Year | G25: Every Day | H25: 6 -- 10 | I25: 4 | J25: 4 | K25: 5 | L25: 5 | M25: 5 | N25: 5 | O25: 5 | P25: 4 | Q25: 4 | R25: 4 | S25: 5 | T25: 4 | U25: 4 | V25: 5 | W25: 4 | X25: 4 | Y25: 4 | Z25: 4 | AA25: 5 | AB25: 4 | AC25: 4 | AD25: 5 | AE25: 4 | AF25: 4 | AG25: 4 | AH25: 4 | AI25: 4 | AJ25: 4 | AK25: 4 | AL25: 4 | AM25: 4 | AN25: 4 | AO25: 4 | AP25: 4

Sheet Driver Responses
A1: Driver Responses
A2: One row per tricycle driver respondent, using the driver instrument.
I3: The system is easy to navigate and use. | J3: The interface is clean and visually understandable. | K3: I was able to register and set up my account without difficulty. | L3: The instructions and labels in the system are clear and easy to understand. | M3: I can comfortably use the system without any technical assistance. | N3: The ride request feature works as expected. | O3: I receive timely notifications about incoming ride requests. | P3: The system accurately shows my availability status to passengers. | Q3: I can manage and track my rides through the system in real time. | R3: The system performs all its intended functions correctly. | S3: The system reduces my idle time waiting for passengers. | T3: Managing ride requests through the system is faster than the manual process. | U3: The system responds quickly to my inputs and actions. | V3: The system helps me serve more passengers throughout the day. | W3: Overall, the system improves my daily work experience as a driver. | X3: The system works consistently without errors or crashes. | Y3: I can depend on the system to deliver ride requests accurately. | Z3: The system maintains accurate and up-to-date information. | AA3: The system performs well even during busy hours. | AB3: I trust the system to support my work as a registered driver.
A4: Respondent No. | B4: Name (optional) | C4: Age | D4: Gender | E4: Years of driving experience | F4: Owns smartphone | G4: Internet access | H4: Average trips per day | I4: A1 | J4: A2 | K4: A3 | L4: A4 | M4: A5 | N4: B1 | O4: B2 | P4: B3 | Q4: B4 | R4: B5 | S4: C1 | T4: C2 | U4: C3 | V4: C4 | W4: C5 | X4: D1 | Y4: D2 | Z4: D3 | AA4: D4 | AB4: D5
A5: EXAMPLE - delete | B5: Pedro Santos | C5: 41 | D5: Male | E5: 4-6 years | F5: Yes | G5: Yes | H5: 11-15 | I5: 5 | J5: 4 | K5: 5 | L5: 4 | M5: 5 | N5: 5 | O5: 4 | P5: 5 | Q5: 4 | R5: 5 | S5: 5 | T5: 4 | U5: 5 | V5: 4 | W5: 5 | X5: 5 | Y5: 4 | Z5: 5 | AA5: 4 | AB5: 5
A6: 1 | B6: Name (optional) | C6: 50 | D6: Male | E6: More than 10 years | F6: Yes | G6: Yes | H6: 21 or more | I6: 4 | J6: 4 | K6: 5 | L6: 4 | M6: 5 | N6: 5 | O6: 5 | P6: 4 | Q6: 5 | R6: 4 | S6: 5 | T6: 4 | U6: 5 | V6: 4 | W6: 5 | X6: 4 | Y6: 5 | Z6: 4 | AA6: 5 | AB6: 5
A7: 2 | B7: Name (optional) | C7: 41 | D7: Male | E7: 7 - 10 years | F7: Yes | G7: Yes | H7: 11 -- 15 | I7: 3 | J7: 3 | K7: 4 | L7: 4 | M7: 4 | N7: 4 | O7: 3 | P7: 4 | Q7: 4 | R7: 5 | S7: 4 | T7: 5 | U7: 4 | V7: 5 | W7: 4 | X7: 5 | Y7: 4 | Z7: 5 | AA7: 3 | AB7: 5
A8: 3 | B8: Name (optional) | C8: 58 | D8: Male | E8: More than 10 years | F8: Yes | G8: Yes | H8: 6 -- 10 | I8: 4 | J8: 4 | K8: 4 | L8: 4 | M8: 4 | N8: 4 | O8: 5 | P8: 4 | Q8: 4 | R8: 5 | S8: 4 | T8: 4 | U8: 4 | V8: 5 | W8: 4 | X8: 5 | Y8: 4 | Z8: 4 | AA8: 5 | AB8: 4
A9: 4 | B9: Name (optional) | C9: 45 | D9: Male | E9: 7 - 10 years | F9: Yes | G9: Yes | H9: 6 -- 10 | I9: 5 | J9: 4 | K9: 5 | L9: 4 | M9: 3 | N9: 5 | O9: 5 | P9: 5 | Q9: 4 | R9: 5 | S9: 5 | T9: 4 | U9: 4 | V9: 5 | W9: 4 | X9: 5 | Y9: 5 | Z9: 4 | AA9: 4 | AB9: 5
A10: 5 | B10: Name (optional) | C10: 64 | D10: Male | E10: More than 10 years | F10: Yes | G10: Yes | H10: 1 -- 5 | I10: 5 | J10: 4 | K10: 4 | L10: 4 | M10: 4 | N10: 4 | O10: 4 | P10: 4 | Q10: 4 | R10: 4 | S10: 4 | T10: 4 | U10: 4 | V10: 4 | W10: 4 | X10: 4 | Y10: 4 | Z10: 4 | AA10: 4 | AB10: 5
A11: 6 | B11: Name (optional) | C11: 54 | D11: Male | E11: More than 10 years | F11: Yes | G11: Yes | H11: 6 -- 10 | I11: 5 | J11: 5 | K11: 5 | L11: 5 | M11: 5 | N11: 5 | O11: 5 | P11: 5 | Q11: 5 | R11: 5 | S11: 5 | T11: 5 | U11: 5 | V11: 5 | W11: 5 | X11: 5 | Y11: 5 | Z11: 5 | AA11: 5 | AB11: 5
A12: 7 | B12: Name (optional) | C12: 48 | D12: Male | E12: More than 10 years | F12: Yes | G12: Yes | H12: 6 -- 10 | I12: 4 | J12: 4 | K12: 4 | L12: 4 | M12: 4 | N12: 4 | O12: 4 | P12: 4 | Q12: 4 | R12: 4 | S12: 4 | T12: 4 | U12: 4 | V12: 4 | W12: 4 | X12: 4 | Y12: 4 | Z12: 4 | AA12: 4 | AB12: 4
A13: 8 | B13: Name (optional) | C13: 45 | D13: Male | E13: 1 - 3 years | F13: Yes | G13: Yes | H13: 1 -- 5 | I13: 5 | J13: 4 | K13: 4 | L13: 4 | M13: 4 | N13: 4 | O13: 4 | P13: 4 | Q13: 4 | R13: 4 | S13: 4 | T13: 4 | U13: 4 | V13: 5 | W13: 5 | X13: 5 | Y13: 5 | Z13: 4 | AA13: 4 | AB13: 5
A14: 9 | B14: Name (optional) | C14: 68 | D14: Male | E14: More than 10 years | F14: Yes | G14: Yes | H14: 1 -- 5 | I14: 5 | J14: 4 | K14: 5 | L14: 4 | M14: 4 | N14: 4 | O14: 5 | P14: 5 | Q14: 4 | R14: 3 | S14: 4 | T14: 5 | U14: 4 | V14: 4 | W14: 3 | X14: 4 | Y14: 4 | Z14: 5 | AA14: 4 | AB14: 5
A15: 10 | B15: Name (optional) | C15: 56 | D15: Male | E15: More than 10 years | F15: Yes | G15: Yes | H15: 1 -- 5 | I15: 5 | J15: 4 | K15: 4 | L15: 4 | M15: 4 | N15: 4 | O15: 4 | P15: 4 | Q15: 3 | R15: 4 | S15: 4 | T15: 4 | U15: 4 | V15: 4 | W15: 5 | X15: 5 | Y15: 4 | Z15: 4 | AA15: 4 | AB15: 4
A16: 11 | B16: Name (optional) | C16: 45 | D16: Male | E16: 7 - 10 years | F16: Yes | G16: Yes | H16: 1 -- 5 | I16: 4 | J16: 4 | K16: 4 | L16: 4 | M16: 4 | N16: 4 | O16: 4 | P16: 4 | Q16: 4 | R16: 4 | S16: 4 | T16: 4 | U16: 4 | V16: 4 | W16: 4 | X16: 4 | Y16: 4 | Z16: 4 | AA16: 4 | AB16: 4
A17: 12 | B17: Name (optional) | C17: 67 | D17: Male | E17: More than 10 years | F17: Yes | G17: Yes | H17: 1 -- 5 | I17: 4 | J17: 4 | K17: 4 | L17: 4 | M17: 4 | N17: 4 | O17: 4 | P17: 4 | Q17: 4 | R17: 4 | S17: 4 | T17: 4 | U17: 4 | V17: 4 | W17: 4 | X17: 4 | Y17: 4 | Z17: 4 | AA17: 4 | AB17: 5
... A25: 20 | B25: Name (optional) | C25: 52 | D25: Male | E25: More than 10 years | F25: Yes | G25: Yes | H25: 6 -- 10 | I25: 5 | J25: 4 | K25: 4 | L25: 4 | M25: 4 | N25: 4 | O25: 4 | P25: 4 | Q25: 4 | R25: 4 | S25: 4 | T25: 4 | U25: 4 | V25: 5 | W25: 4 | X25: 4 | Y25: 5 | Z25: 5 | AA25: 5 | AB25: 4

Sheet Admin Responses
A1: Admin Responses
A2: Part III, answered by the system administrator.
E3: I can approve driver applications. | F3: I can monitor ride activities. | G3: I can manage user accounts. | H3: The dashboard is easy to use. | I3: Reports are easy to generate. | J3: Records are accurate. | K3: Data updates correctly.
A4: Respondent No. | B4: Name (optional) | C4: Age | D4: Gender | E4: A1 | F4: A2 | G4: A3 | H4: B1 | I4: B2 | J4: C1 | K4: C2
A5: EXAMPLE - delete | B5: Maria Reyes | C5: 33 | D5: Female | E5: 5 | F5: 4 | G5: 5 | H5: 4 | I5: 5 | J5: 5 | K5: 4
A6: 1 | B6: Name (optional) | C6: 22 | D6: Male | E6: 5 | F6: 5 | G6: 5 | H6: 5 | I6: 5 | J6: 4 | K6: 4

Sheet Tally - Passenger
A1: Tally - Passenger
A2: Every figure is a formula reading 'Passenger Responses' rows 6-205. Nothing on this sheet needs typing.
A4: # | B4: Indicator | C4: 5 | D4: 4 | E4: 3 | F4: 2 | G4: 1 | H4: N | I4: Weighted Mean | J4: Interpretation
A5: A. Functional Suitability
A6: 1 | B6: The ride booking feature works as expected. | C6: =COUNTIF('Passenger Responses'!$I$6:$I$25,5) -> 3 | D6: =COUNTIF('Passenger Responses'!$I$6:$I$25,4) -> 16 | E6: =COUNTIF('Passenger Responses'!$I$6:$I$25,3) -> 1 | F6: =COUNTIF('Passenger Responses'!$I$6:$I$25,2) -> 0 | G6: =COUNTIF('Passenger Responses'!$I$6:$I$25,1) -> 0 | H6: =COUNT('Passenger Responses'!$I$6:$I$25) -> 20 | I6: =IF(H6=0,"",(C6*5+D6*4+E6*3+F6*2+G6*1)/H6) -> 4.1 | J6: =IF(I6="","",IF(I6>=4.21,"Strongly Agree",IF(I6>=3.41,"Agree",IF(I6>=2.61,"Neutral",IF(I6>=1.81,"Disagree","Strongly Disagree"))))) -> Agree
A7: 2 | B7: I receive timely notifications about my ride status. | C7: =COUNTIF('Passenger Responses'!$J$6:$J$25,5) -> 1 | D7: =COUNTIF('Passenger Responses'!$J$6:$J$25,4) -> 19 | E7: =COUNTIF('Passenger Responses'!$J$6:$J$25,3) -> 0 | F7: =COUNTIF('Passenger Responses'!$J$6:$J$25,2) -> 0 | G7: =COUNTIF('Passenger Responses'!$J$6:$J$25,1) -> 0 | H7: =COUNT('Passenger Responses'!$J$6:$J$25) -> 20 | I7: =IF(H7=0,"",(C7*5+D7*4+E7*3+F7*2+G7*1)/H7) -> 4.05 | J7: =IF(I7="","",IF(I7>=4.21,"Strongly Agree",IF(I7>=3.41,"Agree",IF(I7>=2.61,"Neutral",IF(I7>=1.81,"Disagree","Strongly Disagree"))))) -> Agree
A8: 3 | B8: The system accurately matches me with an available driver. | C8: =COUNTIF('Passenger Responses'!$K$6:$K$25,5) -> 10 | D8: =COUNTIF('Passenger Responses'!$K$6:$K$25,4) -> 9 | E8: =COUNTIF('Passenger Responses'!$K$6:$K$25,3) -> 1 | F8: =COUNTIF('Passenger Responses'!$K$6:$K$25,2) -> 0 | G8: =COUNTIF('Passenger Responses'!$K$6:$K$25,1) -> 0 | H8: =COUNT('Passenger Responses'!$K$6:$K$25) -> 20 | I8: =IF(H8=0,"",(C8*5+D8*4+E8*3+F8*2+G8*1)/H8) -> 4.45 | J8: =IF(I8="","",IF(I8>=4.21,"Strongly Agree",IF(I8>=3.41,"Agree",IF(I8>=2.61,"Neutral",IF(I8>=1.81,"Disagree","Strongly Disagree"))))) -> Strongly Agree
A9: 4 | B9: I can view the status of my booking in real time. | C9: =COUNTIF('Passenger Responses'!$L$6:$L$25,5) -> 4 | D9: =COUNTIF('Passenger Responses'!$L$6:$L$25,4) -> 14 | E9: =COUNTIF('Passenger Responses'!$L$6:$L$25,3) -> 2 | F9: =COUNTIF('Passenger Responses'!$L$6:$L$25,2) -> 0 | G9: =COUNTIF('Passenger Responses'!$L$6:$L$25,1) -> 0 | H9: =COUNT('Passenger Responses'!$L$6:$L$25) -> 20 | I9: =IF(H9=0,"",(C9*5+D9*4+E9*3+F9*2+G9*1)/H9) -> 4.1 | J9: =IF(I9="","",IF(I9>=4.21,"Strongly Agree",IF(I9>=3.41,"Agree",IF(I9>=2.61,"Neutral",IF(I9>=1.81,"Disagree","Strongly Disagree"))))) -> Agree
A10: 5 | B10: The system performs all its intended functions correctly. | C10: =COUNTIF('Passenger Responses'!$M$6:$M$25,5) -> 9 | D10: =COUNTIF('Passenger Responses'!$M$6:$M$25,4) -> 10 | E10: =COUNTIF('Passenger Responses'!$M$6:$M$25,3) -> 1 | F10: =COUNTIF('Passenger Responses'!$M$6:$M$25,2) -> 0 | G10: =COUNTIF('Passenger Responses'!$M$6:$M$25,1) -> 0 | H10: =COUNT('Passenger Responses'!$M$6:$M$25) -> 20 | I10: =IF(H10=0,"",(C10*5+D10*4+E10*3+F10*2+G10*1)/H10) -> 4.4 | J10: =IF(I10="","",IF(I10>=4.21,"Strongly Agree",IF(I10>=3.41,"Agree",IF(I10>=2.61,"Neutral",IF(I10>=1.81,"Disagree","Strongly Disagree"))))) -> Strongly Agree
A11: 6 | B11: The fare displayed is accurate. | C11: =COUNTIF('Passenger Responses'!$N$6:$N$25,5) -> 5 | D11: =COUNTIF('Passenger Responses'!$N$6:$N$25,4) -> 15 | E11: =COUNTIF('Passenger Responses'!$N$6:$N$25,3) -> 0 | F11: =COUNTIF('Passenger Responses'!$N$6:$N$25,2) -> 0 | G11: =COUNTIF('Passenger Responses'!$N$6:$N$25,1) -> 0 | H11: =COUNT('Passenger Responses'!$N$6:$N$25) -> 20 | I11: =IF(H11=0,"",(C11*5+D11*4+E11*3+F11*2+G11*1)/H11) -> 4.25 | J11: =IF(I11="","",IF(I11>=4.21,"Strongly Agree",IF(I11>=3.41,"Agree",IF(I11>=2.61,"Neutral",IF(I11>=1.81,"Disagree","Strongly Disagree"))))) -> Strongly Agree
A12: 7 | B12: Driver information is correctly displayed. | C12: =COUNTIF('Passenger Responses'!$O$6:$O$25,5) -> 5 | D12: =COUNTIF('Passenger Responses'!$O$6:$O$25,4) -> 15 | E12: =COUNTIF('Passenger Responses'!$O$6:$O$25,3) -> 0 | F12: =COUNTIF('Passenger Responses'!$O$6:$O$25,2) -> 0 | G12: =COUNTIF('Passenger Responses'!$O$6:$O$25,1) -> 0 | H12: =COUNT('Passenger Responses'!$O$6:$O$25) -> 20 | I12: =IF(H12=0,"",(C12*5+D12*4+E12*3+F12*2+G12*1)/H12) -> 4.25 | J12: =IF(I12="","",IF(I12>=4.21,"Strongly Agree",IF(I12>=3.41,"Agree",IF(I12>=2.61,"Neutral",IF(I12>=1.81,"Disagree","Strongly Disagree"))))) -> Strongly Agree
A13: 8 | B13: Ride history is properly recorded. | C13: =COUNTIF('Passenger Responses'!$P$6:$P$25,5) -> 4 | D13: =COUNTIF('Passenger Responses'!$P$6:$P$25,4) -> 16 | E13: =COUNTIF('Passenger Responses'!$P$6:$P$25,3) -> 0 | F13: =COUNTIF('Passenger Responses'!$P$6:$P$25,2) -> 0 | G13: =COUNTIF('Passenger Responses'!$P$6:$P$25,1) -> 0 | H13: =COUNT('Passenger Responses'!$P$6:$P$25) -> 20 | I13: =IF(H13=0,"",(C13*5+D13*4+E13*3+F13*2+G13*1)/H13) -> 4.2 | J13: =IF(I13="","",IF(I13>=4.21,"Strongly Agree",IF(I13>=3.41,"Agree",IF(I13>=2.61,"Neutral",IF(I13>=1.81,"Disagree","Strongly Disagree"))))) -> Agree
B14: Category mean — A. Functional Suitability | I14: =IFERROR(AVERAGE(I6:I13),"") -> 4.225 | J14: =IF(I14="","",IF(I14>=4.21,"Strongly Agree",IF(I14>=3.41,"Agree",IF(I14>=2.61,"Neutral",IF(I14>=1.81,"Disagree","Strongly Disagree"))))) -> Strongly Agree
A16: B. Usability
A17: 1 | B17: The system is easy to learn. | C17: =COUNTIF('Passenger Responses'!$Q$6:$Q$25,5) -> 7 | D17: =COUNTIF('Passenger Responses'!$Q$6:$Q$25,4) -> 13 | E17: =COUNTIF('Passenger Responses'!$Q$6:$Q$25,3) -> 0 | F17: =COUNTIF('Passenger Responses'!$Q$6:$Q$25,2) -> 0 | G17: =COUNTIF('Passenger Responses'!$Q$6:$Q$25,1) -> 0 | H17: =COUNT('Passenger Responses'!$Q$6:$Q$25) -> 20 | I17: =IF(H17=0,"",(C17*5+D17*4+E17*3+F17*2+G17*1)/H17) -> 4.35 | J17: =IF(I17="","",IF(I17>=4.21,"Strongly Agree",IF(I17>=3.41,"Agree",IF(I17>=2.61,"Neutral",IF(I17>=1.81,"Disagree","Strongly Disagree"))))) -> Strongly Agree
A18: 2 | B18: The menus are easy to understand. | C18: =COUNTIF('Passenger Responses'!$R$6:$R$25,5) -> 8 | D18: =COUNTIF('Passenger Responses'!$R$6:$R$25,4) -> 12 | E18: =COUNTIF('Passenger Responses'!$R$6:$R$25,3) -> 0 | F18: =COUNTIF('Passenger Responses'!$R$6:$R$25,2) -> 0 | G18: =COUNTIF('Passenger Responses'!$R$6:$R$25,1) -> 0 | H18: =COUNT('Passenger Responses'!$R$6:$R$25) -> 20 | I18: =IF(H18=0,"",(C18*5+D18*4+E18*3+F18*2+G18*1)/H18) -> 4.4 | J18: =IF(I18="","",IF(I18>=4.21,"Strongly Agree",IF(I18>=3.41,"Agree",IF(I18>=2.61,"Neutral",IF(I18>=1.81,"Disagree","Strongly Disagree"))))) -> Strongly Agree
A19: 3 | B19: Icons and buttons are properly labeled. | C19: =COUNTIF('Passenger Responses'!$S$6:$S$25,5) -> 8 | D19: =COUNTIF('Passenger Responses'!$S$6:$S$25,4) -> 12 | E19: =COUNTIF('Passenger Responses'!$S$6:$S$25,3) -> 0 | F19: =COUNTIF('Passenger Responses'!$S$6:$S$25,2) -> 0 | G19: =COUNTIF('Passenger Responses'!$S$6:$S$25,1) -> 0 | H19: =COUNT('Passenger Responses'!$S$6:$S$25) -> 20 | I19: =IF(H19=0,"",(C19*5+D19*4+E19*3+F19*2+G19*1)/H19) -> 4.4 | J19: =IF(I19="","",IF(I19>=4.21,"Strongly Agree",IF(I19>=3.41,"Agree",IF(I19>=2.61,"Neutral",IF(I19>=1.81,"Disagree","Strongly Disagree"))))) -> Strongly Agree
A20: 4 | B20: The interface is visually appealing. | C20: =COUNTIF('Passenger Responses'!$T$6:$T$25,5) -> 7 | D20: =COUNTIF('Passenger Responses'!$T$6:$T$25,4) -> 12 | E20: =COUNTIF('Passenger Responses'!$T$6:$T$25,3) -> 1 | F20: =COUNTIF('Passenger Responses'!$T$6:$T$25,2) -> 0 | G20: =COUNTIF('Passenger Responses'!$T$6:$T$25,1) -> 0 | H20: =COUNT('Passenger Responses'!$T$6:$T$25) -> 20 | I20: =IF(H20=0,"",(C20*5+D20*4+E20*3+F20*2+G20*1)/H20) -> 4.3 | J20: =IF(I20="","",IF(I20>=4.21,"Strongly Agree",IF(I20>=3.41,"Agree",IF(I20>=2.61,"Neutral",IF(I20>=1.81,"Disagree","Strongly Disagree"))))) -> Strongly Agree
A21: 5 | B21: I can complete my tasks without confusion. | C21: =COUNTIF('Passenger Responses'!$U$6:$U$25,5) -> 9 | D21: =COUNTIF('Passenger Responses'!$U$6:$U$25,4) -> 11 | E21: =COUNTIF('Passenger Responses'!$U$6:$U$25,3) -> 0 | F21: =COUNTIF('Passenger Responses'!$U$6:$U$25,2) -> 0 | G21: =COUNTIF('Passenger Responses'!$U$6:$U$25,1) -> 0 | H21: =COUNT('Passenger Responses'!$U$6:$U$25) -> 20 | I21: =IF(H21=0,"",(C21*5+D21*4+E21*3+F21*2+G21*1)/H21) -> 4.45 | J21: =IF(I21="","",IF(I21>=4.21,"Strongly Agree",IF(I21>=3.41,"Agree",IF(I21>=2.61,"Neutral",IF(I21>=1.81,"Disagree","Strongly Disagree"))))) -> Strongly Agree
A22: 6 | B22: The system is easy to learn. | C22: =COUNTIF('Passenger Responses'!$V$6:$V$25,5) -> 7 | D22: =COUNTIF('Passenger Responses'!$V$6:$V$25,4) -> 13 | E22: =COUNTIF('Passenger Responses'!$V$6:$V$25,3) -> 0 | F22: =COUNTIF('Passenger Responses'!$V$6:$V$25,2) -> 0 | G22: =COUNTIF('Passenger Responses'!$V$6:$V$25,1) -> 0 | H22: =COUNT('Passenger Responses'!$V$6:$V$25) -> 20 | I22: =IF(H22=0,"",(C22*5+D22*4+E22*3+F22*2+G22*1)/H22) -> 4.35 | J22: =IF(I22="","",IF(I22>=4.21,"Strongly Agree",IF(I22>=3.41,"Agree",IF(I22>=2.61,"Neutral",IF(I22>=1.81,"Disagree","Strongly Disagree"))))) -> Strongly Agree
B23: Category mean — B. Usability | I23: =IFERROR(AVERAGE(I17:I22),"") -> 4.375 | J23: =IF(I23="","",IF(I23>=4.21,"Strongly Agree",IF(I23>=3.41,"Agree",IF(I23>=2.61,"Neutral",IF(I23>=1.81,"Disagree","Strongly Disagree"))))) -> Strongly Agree
A25: C. Efficiency
A26: 1 | B26: The application loads quickly. | C26: =COUNTIF('Passenger Responses'!$W$6:$W$25,5) -> 6 | D26: =COUNTIF('Passenger Responses'!$W$6:$W$25,4) -> 14 | E26: =COUNTIF('Passenger Responses'!$W$6:$W$25,3) -> 0 | F26: =COUNTIF('Passenger Responses'!$W$6:$W$25,2) -> 0 | G26: =COUNTIF('Passenger Responses'!$W$6:$W$25,1) -> 0 | H26: =COUNT('Passenger Responses'!$W$6:$W$25) -> 20 | I26: =IF(H26=0,"",(C26*5+D26*4+E26*3+F26*2+G26*1)/H26) -> 4.3 | J26: =IF(I26="","",IF(I26>=4.21,"Strongly Agree",IF(I26>=3.41,"Agree",IF(I26>=2.61,"Neutral",IF(I26>=1.81,"Disagree","Strongly Disagree"))))) -> Strongly Agree
A27: 2 | B27: Booking requests are processed immediately. | C27: =COUNTIF('Passenger Responses'!$X$6:$X$25,5) -> 4 | D27: =COUNTIF('Passenger Responses'!$X$6:$X$25,4) -> 16 | E27: =COUNTIF('Passenger Responses'!$X$6:$X$25,3) -> 0 | F27: =COUNTIF('Passenger Responses'!$X$6:$X$25,2) -> 0 | G27: =COUNTIF('Passenger Responses'!$X$6:$X$25,1) -> 0 | H27: =COUNT('Passenger Responses'!$X$6:$X$25) -> 20 | I27: =IF(H27=0,"",(C27*5+D27*4+E27*3+F27*2+G27*1)/H27) -> 4.2 | J27: =IF(I27="","",IF(I27>=4.21,"Strongly Agree",IF(I27>=3.41,"Agree",IF(I27>=2.61,"Neutral",IF(I27>=1.81,"Disagree","Strongly Disagree"))))) -> Agree
A28: 3 | B28: Notifications arrive without delay. | C28: =COUNTIF('Passenger Responses'!$Y$6:$Y$25,5) -> 3 | D28: =COUNTIF('Passenger Responses'!$Y$6:$Y$25,4) -> 15 | E28: =COUNTIF('Passenger Responses'!$Y$6:$Y$25,3) -> 2 | F28: =COUNTIF('Passenger Responses'!$Y$6:$Y$25,2) -> 0 | G28: =COUNTIF('Passenger Responses'!$Y$6:$Y$25,1) -> 0 | H28: =COUNT('Passenger Responses'!$Y$6:$Y$25) -> 20 | I28: =IF(H28=0,"",(C28*5+D28*4+E28*3+F28*2+G28*1)/H28) -> 4.05 | J28: =IF(I28="","",IF(I28>=4.21,"Strongly Agree",IF(I28>=3.41,"Agree",IF(I28>=2.61,"Neutral",IF(I28>=1.81,"Disagree","Strongly Disagree"))))) -> Agree
A29: 4 | B29: The system performs smoothly. | C29: =COUNTIF('Passenger Responses'!$Z$6:$Z$25,5) -> 7 | D29: =COUNTIF('Passenger Responses'!$Z$6:$Z$25,4) -> 12 | E29: =COUNTIF('Passenger Responses'!$Z$6:$Z$25,3) -> 1 | F29: =COUNTIF('Passenger Responses'!$Z$6:$Z$25,2) -> 0 | G29: =COUNTIF('Passenger Responses'!$Z$6:$Z$25,1) -> 0 | H29: =COUNT('Passenger Responses'!$Z$6:$Z$25) -> 20 | I29: =IF(H29=0,"",(C29*5+D29*4+E29*3+F29*2+G29*1)/H29) -> 4.3 | J29: =IF(I29="","",IF(I29>=4.21,"Strongly Agree",IF(I29>=3.41,"Agree",IF(I29>=2.61,"Neutral",IF(I29>=1.81,"Disagree","Strongly Disagree"))))) -> Strongly Agree
A30: 5 | B30: The application consumes minimal mobile resources. | C30: =COUNTIF('Passenger Responses'!$AA$6:$AA$25,5) -> 8 | D30: =COUNTIF('Passenger Responses'!$AA$6:$AA$25,4) -> 12 | E30: =COUNTIF('Passenger Responses'!$AA$6:$AA$25,3) -> 0 | F30: =COUNTIF('Passenger Responses'!$AA$6:$AA$25,2) -> 0 | G30: =COUNTIF('Passenger Responses'!$AA$6:$AA$25,1) -> 0 | H30: =COUNT('Passenger Responses'!$AA$6:$AA$25) -> 20 | I30: =IF(H30=0,"",(C30*5+D30*4+E30*3+F30*2+G30*1)/H30) -> 4.4 | J30: =IF(I30="","",IF(I30>=4.21,"Strongly Agree",IF(I30>=3.41,"Agree",IF(I30>=2.61,"Neutral",IF(I30>=1.81,"Disagree","Strongly Disagree"))))) -> Strongly Agree
B31: Category mean — C. Efficiency | I31: =IFERROR(AVERAGE(I26:I30),"") -> 4.25 | J31: =IF(I31="","",IF(I31>=4.21,"Strongly Agree",IF(I31>=3.41,"Agree",IF(I31>=2.61,"Neutral",IF(I31>=1.81,"Disagree","Strongly Disagree"))))) -> Strongly Agree
A33: D. Reliability
A34: 1 | B34: The system recovers properly after connection interruptions. | C34: =COUNTIF('Passenger Responses'!$AB$6:$AB$25,5) -> 8 | D34: =COUNTIF('Passenger Responses'!$AB$6:$AB$25,4) -> 12 | E34: =COUNTIF('Passenger Responses'!$AB$6:$AB$25,3) -> 0 | F34: =COUNTIF('Passenger Responses'!$AB$6:$AB$25,2) -> 0 | G34: =COUNTIF('Passenger Responses'!$AB$6:$AB$25,1) -> 0 | H34: =COUNT('Passenger Responses'!$AB$6:$AB$25) -> 20 | I34: =IF(H34=0,"",(C34*5+D34*4+E34*3+F34*2+G34*1)/H34) -> 4.4 | J34: =IF(I34="","",IF(I34>=4.21,"Strongly Agree",IF(I34>=3.41,"Agree",IF(I34>=2.61,"Neutral",IF(I34>=1.81,"Disagree","Strongly Disagree"))))) -> Strongly Agree
A35: 2 | B35: I can depend on the system to connect me with a driver when needed. | C35: =COUNTIF('Passenger Responses'!$AC$6:$AC$25,5) -> 4 | D35: =COUNTIF('Passenger Responses'!$AC$6:$AC$25,4) -> 16 | E35: =COUNTIF('Passenger Responses'!$AC$6:$AC$25,3) -> 0 | F35: =COUNTIF('Passenger Responses'!$AC$6:$AC$25,2) -> 0 | G35: =COUNTIF('Passenger Responses'!$AC$6:$AC$25,1) -> 0 | H35: =COUNT('Passenger Responses'!$AC$6:$AC$25) -> 20 | I35: =IF(H35=0,"",(C35*5+D35*4+E35*3+F35*2+G35*1)/H35) -> 4.2 | J35: =IF(I35="","",IF(I35>=4.21,"Strongly Agree",IF(I35>=3.41,"Agree",IF(I35>=2.61,"Neutral",IF(I35>=1.81,"Disagree","Strongly Disagree"))))) -> Agree
A36: 3 | B36: The system maintains accurate and up-to-date information. | C36: =COUNTIF('Passenger Responses'!$AD$6:$AD$25,5) -> 5 | D36: =COUNTIF('Passenger Responses'!$AD$6:$AD$25,4) -> 15 | E36: =COUNTIF('Passenger Responses'!$AD$6:$AD$25,3) -> 0 | F36: =COUNTIF('Passenger Responses'!$AD$6:$AD$25,2) -> 0 | G36: =COUNTIF('Passenger Responses'!$AD$6:$AD$25,1) -> 0 | H36: =COUNT('Passenger Responses'!$AD$6:$AD$25) -> 20 | I36: =IF(H36=0,"",(C36*5+D36*4+E36*3+F36*2+G36*1)/H36) -> 4.25 | J36: =IF(I36="","",IF(I36>=4.21,"Strongly Agree",IF(I36>=3.41,"Agree",IF(I36>=2.61,"Neutral",IF(I36>=1.81,"Disagree","Strongly Disagree"))))) -> Strongly Agree
A37: 4 | B37: The system performs well even during peak hours. | C37: =COUNTIF('Passenger Responses'!$AE$6:$AE$25,5) -> 3 | D37: =COUNTIF('Passenger Responses'!$AE$6:$AE$25,4) -> 17 | E37: =COUNTIF('Passenger Responses'!$AE$6:$AE$25,3) -> 0 | F37: =COUNTIF('Passenger Responses'!$AE$6:$AE$25,2) -> 0 | G37: =COUNTIF('Passenger Responses'!$AE$6:$AE$25,1) -> 0 | H37: =COUNT('Passenger Responses'!$AE$6:$AE$25) -> 20 | I37: =IF(H37=0,"",(C37*5+D37*4+E37*3+F37*2+G37*1)/H37) -> 4.15 | J37: =IF(I37="","",IF(I37>=4.21,"Strongly Agree",IF(I37>=3.41,"Agree",IF(I37>=2.61,"Neutral",IF(I37>=1.81,"Disagree","Strongly Disagree"))))) -> Agree
A38: 5 | B38: I trust the system to provide a safe and reliable ride booking experience. | C38: =COUNTIF('Passenger Responses'!$AF$6:$AF$25,5) -> 6 | D38: =COUNTIF('Passenger Responses'!$AF$6:$AF$25,4) -> 14 | E38: =COUNTIF('Passenger Responses'!$AF$6:$AF$25,3) -> 0 | F38: =COUNTIF('Passenger Responses'!$AF$6:$AF$25,2) -> 0 | G38: =COUNTIF('Passenger Responses'!$AF$6:$AF$25,1) -> 0 | H38: =COUNT('Passenger Responses'!$AF$6:$AF$25) -> 20 | I38: =IF(H38=0,"",(C38*5+D38*4+E38*3+F38*2+G38*1)/H38) -> 4.3 | J38: =IF(I38="","",IF(I38>=4.21,"Strongly Agree",IF(I38>=3.41,"Agree",IF(I38>=2.61,"Neutral",IF(I38>=1.81,"Disagree","Strongly Disagree"))))) -> Strongly Agree
B39: Category mean — D. Reliability | I39: =IFERROR(AVERAGE(I34:I38),"") -> 4.26 | J39: =IF(I39="","",IF(I39>=4.21,"Strongly Agree",IF(I39>=3.41,"Agree",IF(I39>=2.61,"Neutral",IF(I39>=1.81,"Disagree","Strongly Disagree"))))) -> Strongly Agree
A41: E. Security
A42: 1 | B42: I feel that my personal information is protected. | C42: =COUNTIF('Passenger Responses'!$AG$6:$AG$25,5) -> 7 | D42: =COUNTIF('Passenger Responses'!$AG$6:$AG$25,4) -> 13 | E42: =COUNTIF('Passenger Responses'!$AG$6:$AG$25,3) -> 0 | F42: =COUNTIF('Passenger Responses'!$AG$6:$AG$25,2) -> 0 | G42: =COUNTIF('Passenger Responses'!$AG$6:$AG$25,1) -> 0 | H42: =COUNT('Passenger Responses'!$AG$6:$AG$25) -> 20 | I42: =IF(H42=0,"",(C42*5+D42*4+E42*3+F42*2+G42*1)/H42) -> 4.35 | J42: =IF(I42="","",IF(I42>=4.21,"Strongly Agree",IF(I42>=3.41,"Agree",IF(I42>=2.61,"Neutral",IF(I42>=1.81,"Disagree","Strongly Disagree"))))) -> Strongly Agree
A43: 2 | B43: The login process is secure. | C43: =COUNTIF('Passenger Responses'!$AH$6:$AH$25,5) -> 8 | D43: =COUNTIF('Passenger Responses'!$AH$6:$AH$25,4) -> 12 | E43: =COUNTIF('Passenger Responses'!$AH$6:$AH$25,3) -> 0 | F43: =COUNTIF('Passenger Responses'!$AH$6:$AH$25,2) -> 0 | G43: =COUNTIF('Passenger Responses'!$AH$6:$AH$25,1) -> 0 | H43: =COUNT('Passenger Responses'!$AH$6:$AH$25) -> 20 | I43: =IF(H43=0,"",(C43*5+D43*4+E43*3+F43*2+G43*1)/H43) -> 4.4 | J43: =IF(I43="","",IF(I43>=4.21,"Strongly Agree",IF(I43>=3.41,"Agree",IF(I43>=2.61,"Neutral",IF(I43>=1.81,"Disagree","Strongly Disagree"))))) -> Strongly Agree
A44: 3 | B44: Only authorized users can access their accounts. | C44: =COUNTIF('Passenger Responses'!$AI$6:$AI$25,5) -> 6 | D44: =COUNTIF('Passenger Responses'!$AI$6:$AI$25,4) -> 13 | E44: =COUNTIF('Passenger Responses'!$AI$6:$AI$25,3) -> 1 | F44: =COUNTIF('Passenger Responses'!$AI$6:$AI$25,2) -> 0 | G44: =COUNTIF('Passenger Responses'!$AI$6:$AI$25,1) -> 0 | H44: =COUNT('Passenger Responses'!$AI$6:$AI$25) -> 20 | I44: =IF(H44=0,"",(C44*5+D44*4+E44*3+F44*2+G44*1)/H44) -> 4.25 | J44: =IF(I44="","",IF(I44>=4.21,"Strongly Agree",IF(I44>=3.41,"Agree",IF(I44>=2.61,"Neutral",IF(I44>=1.81,"Disagree","Strongly Disagree"))))) -> Strongly Agree
A45: 4 | B45: Driver information is securely stored. | C45: =COUNTIF('Passenger Responses'!$AJ$6:$AJ$25,5) -> 9 | D45: =COUNTIF('Passenger Responses'!$AJ$6:$AJ$25,4) -> 9 | E45: =COUNTIF('Passenger Responses'!$AJ$6:$AJ$25,3) -> 2 | F45: =COUNTIF('Passenger Responses'!$AJ$6:$AJ$25,2) -> 0 | G45: =COUNTIF('Passenger Responses'!$AJ$6:$AJ$25,1) -> 0 | H45: =COUNT('Passenger Responses'!$AJ$6:$AJ$25) -> 20 | I45: =IF(H45=0,"",(C45*5+D45*4+E45*3+F45*2+G45*1)/H45) -> 4.35 | J45: =IF(I45="","",IF(I45>=4.21,"Strongly Agree",IF(I45>=3.41,"Agree",IF(I45>=2.61,"Neutral",IF(I45>=1.81,"Disagree","Strongly Disagree"))))) -> Strongly Agree
...

Sheet Tally - Driver
A1: Tally - Driver
A2: Every figure is a formula reading 'Driver Responses' rows 6-205. Nothing on this sheet needs typing.
A4: # | B4: Indicator | C4: 5 | D4: 4 | E4: 3 | F4: 2 | G4: 1 | H4: N | I4: Weighted Mean | J4: Interpretation
A5: A. Usability
A6: 1 | B6: The system is easy to navigate and use. | C6: =COUNTIF('Driver Responses'!$I$6:$I$25,5) -> 8 | D6: =COUNTIF('Driver Responses'!$I$6:$I$25,4) -> 11 | E6: =COUNTIF('Driver Responses'!$I$6:$I$25,3) -> 1 | F6: =COUNTIF('Driver Responses'!$I$6:$I$25,2) -> 0 | G6: =COUNTIF('Driver Responses'!$I$6:$I$25,1) -> 0 | H6: =COUNT('Driver Responses'!$I$6:$I$25) -> 20 | I6: =IF(H6=0,"",(C6*5+D6*4+E6*3+F6*2+G6*1)/H6) -> 4.35 | J6: =IF(I6="","",IF(I6>=4.21,"Strongly Agree",IF(I6>=3.41,"Agree",IF(I6>=2.61,"Neutral",IF(I6>=1.81,"Disagree","Strongly Disagree"))))) -> Strongly Agree
A7: 2 | B7: The interface is clean and visually understandable. | C7: =COUNTIF('Driver Responses'!$J$6:$J$25,5) -> 3 | D7: =COUNTIF('Driver Responses'!$J$6:$J$25,4) -> 16 | E7: =COUNTIF('Driver Responses'!$J$6:$J$25,3) -> 1 | F7: =COUNTIF('Driver Responses'!$J$6:$J$25,2) -> 0 | G7: =COUNTIF('Driver Responses'!$J$6:$J$25,1) -> 0 | H7: =COUNT('Driver Responses'!$J$6:$J$25) -> 20 | I7: =IF(H7=0,"",(C7*5+D7*4+E7*3+F7*2+G7*1)/H7) -> 4.1 | J7: =IF(I7="","",IF(I7>=4.21,"Strongly Agree",IF(I7>=3.41,"Agree",IF(I7>=2.61,"Neutral",IF(I7>=1.81,"Disagree","Strongly Disagree"))))) -> Agree
A8: 3 | B8: I was able to register and set up my account without difficulty. | C8: =COUNTIF('Driver Responses'!$K$6:$K$25,5) -> 6 | D8: =COUNTIF('Driver Responses'!$K$6:$K$25,4) -> 14 | E8: =COUNTIF('Driver Responses'!$K$6:$K$25,3) -> 0 | F8: =COUNTIF('Driver Responses'!$K$6:$K$25,2) -> 0 | G8: =COUNTIF('Driver Responses'!$K$6:$K$25,1) -> 0 | H8: =COUNT('Driver Responses'!$K$6:$K$25) -> 20 | I8: =IF(H8=0,"",(C8*5+D8*4+E8*3+F8*2+G8*1)/H8) -> 4.3 | J8: =IF(I8="","",IF(I8>=4.21,"Strongly Agree",IF(I8>=3.41,"Agree",IF(I8>=2.61,"Neutral",IF(I8>=1.81,"Disagree","Strongly Disagree"))))) -> Strongly Agree
A9: 4 | B9: The instructions and labels in the system are clear and easy to understand. | C9: =COUNTIF('Driver Responses'!$L$6:$L$25,5) -> 3 | D9: =COUNTIF('Driver Responses'!$L$6:$L$25,4) -> 16 | E9: =COUNTIF('Driver Responses'!$L$6:$L$25,3) -> 1 | F9: =COUNTIF('Driver Responses'!$L$6:$L$25,2) -> 0 | G9: =COUNTIF('Driver Responses'!$L$6:$L$25,1) -> 0 | H9: =COUNT('Driver Responses'!$L$6:$L$25) -> 20 | I9: =IF(H9=0,"",(C9*5+D9*4+E9*3+F9*2+G9*1)/H9) -> 4.1 | J9: =IF(I9="","",IF(I9>=4.21,"Strongly Agree",IF(I9>=3.41,"Agree",IF(I9>=2.61,"Neutral",IF(I9>=1.81,"Disagree","Strongly Disagree"))))) -> Agree
A10: 5 | B10: I can comfortably use the system without any technical assistance. | C10: =COUNTIF('Driver Responses'!$M$6:$M$25,5) -> 5 | D10: =COUNTIF('Driver Responses'!$M$6:$M$25,4) -> 13 | E10: =COUNTIF('Driver Responses'!$M$6:$M$25,3) -> 2 | F10: =COUNTIF('Driver Responses'!$M$6:$M$25,2) -> 0 | G10: =COUNTIF('Driver Responses'!$M$6:$M$25,1) -> 0 | H10: =COUNT('Driver Responses'!$M$6:$M$25) -> 20 | I10: =IF(H10=0,"",(C10*5+D10*4+E10*3+F10*2+G10*1)/H10) -> 4.15 | J10: =IF(I10="","",IF(I10>=4.21,"Strongly Agree",IF(I10>=3.41,"Agree",IF(I10>=2.61,"Neutral",IF(I10>=1.81,"Disagree","Strongly Disagree"))))) -> Agree
B11: Category mean — A. Usability | I11: =IFERROR(AVERAGE(I6:I10),"") -> 4.2 | J11: =IF(I11="","",IF(I11>=4.21,"Strongly Agree",IF(I11>=3.41,"Agree",IF(I11>=2.61,"Neutral",IF(I11>=1.81,"Disagree","Strongly Disagree"))))) -> Agree
A13: B. Functionality
A14: 1 | B14: The ride request feature works as expected. | C14: =COUNTIF('Driver Responses'!$N$6:$N$25,5) -> 6 | D14: =COUNTIF('Driver Responses'!$N$6:$N$25,4) -> 14 | E14: =COUNTIF('Driver Responses'!$N$6:$N$25,3) -> 0 | F14: =COUNTIF('Driver Responses'!$N$6:$N$25,2) -> 0 | G14: =COUNTIF('Driver Responses'!$N$6:$N$25,1) -> 0 | H14: =COUNT('Driver Responses'!$N$6:$N$25) -> 20 | I14: =IF(H14=0,"",(C14*5+D14*4+E14*3+F14*2+G14*1)/H14) -> 4.3 | J14: =IF(I14="","",IF(I14>=4.21,"Strongly Agree",IF(I14>=3.41,"Agree",IF(I14>=2.61,"Neutral",IF(I14>=1.81,"Disagree","Strongly Disagree"))))) -> Strongly Agree
A15: 2 | B15: I receive timely notifications about incoming ride requests. | C15: =COUNTIF('Driver Responses'!$O$6:$O$25,5) -> 8 | D15: =COUNTIF('Driver Responses'!$O$6:$O$25,4) -> 11 | E15: =COUNTIF('Driver Responses'!$O$6:$O$25,3) -> 1 | F15: =COUNTIF('Driver Responses'!$O$6:$O$25,2) -> 0 | G15: =COUNTIF('Driver Responses'!$O$6:$O$25,1) -> 0 | H15: =COUNT('Driver Responses'!$O$6:$O$25) -> 20 | I15: =IF(H15=0,"",(C15*5+D15*4+E15*3+F15*2+G15*1)/H15) -> 4.35 | J15: =IF(I15="","",IF(I15>=4.21,"Strongly Agree",IF(I15>=3.41,"Agree",IF(I15>=2.61,"Neutral",IF(I15>=1.81,"Disagree","Strongly Disagree"))))) -> Strongly Agree
A16: 3 | B16: The system accurately shows my availability status to passengers. | C16: =COUNTIF('Driver Responses'!$P$6:$P$25,5) -> 5 | D16: =COUNTIF('Driver Responses'!$P$6:$P$25,4) -> 15 | E16: =COUNTIF('Driver Responses'!$P$6:$P$25,3) -> 0 | F16: =COUNTIF('Driver Responses'!$P$6:$P$25,2) -> 0 | G16: =COUNTIF('Driver Responses'!$P$6:$P$25,1) -> 0 | H16: =COUNT('Driver Responses'!$P$6:$P$25) -> 20 | I16: =IF(H16=0,"",(C16*5+D16*4+E16*3+F16*2+G16*1)/H16) -> 4.25 | J16: =IF(I16="","",IF(I16>=4.21,"Strongly Agree",IF(I16>=3.41,"Agree",IF(I16>=2.61,"Neutral",IF(I16>=1.81,"Disagree","Strongly Disagree"))))) -> Strongly Agree
A17: 4 | B17: I can manage and track my rides through the system in real time. | C17: =COUNTIF('Driver Responses'!$Q$6:$Q$25,5) -> 5 | D17: =COUNTIF('Driver Responses'!$Q$6:$Q$25,4) -> 14 | E17: =COUNTIF('Driver Responses'!$Q$6:$Q$25,3) -> 1 | F17: =COUNTIF('Driver Responses'!$Q$6:$Q$25,2) -> 0 | G17: =COUNTIF('Driver Responses'!$Q$6:$Q$25,1) -> 0 | H17: =COUNT('Driver Responses'!$Q$6:$Q$25) -> 20 | I17: =IF(H17=0,"",(C17*5+D17*4+E17*3+F17*2+G17*1)/H17) -> 4.2 | J17: =IF(I17="","",IF(I17>=4.21,"Strongly Agree",IF(I17>=3.41,"Agree",IF(I17>=2.61,"Neutral",IF(I17>=1.81,"Disagree","Strongly Disagree"))))) -> Agree
A18: 5 | B18: The system performs all its intended functions correctly. | C18: =COUNTIF('Driver Responses'!$R$6:$R$25,5) -> 8 | D18: =COUNTIF('Driver Responses'!$R$6:$R$25,4) -> 10 | E18: =COUNTIF('Driver Responses'!$R$6:$R$25,3) -> 2 | F18: =COUNTIF('Driver Responses'!$R$6:$R$25,2) -> 0 | G18: =COUNTIF('Driver Responses'!$R$6:$R$25,1) -> 0 | H18: =COUNT('Driver Responses'!$R$6:$R$25) -> 20 | I18: =IF(H18=0,"",(C18*5+D18*4+E18*3+F18*2+G18*1)/H18) -> 4.3 | J18: =IF(I18="","",IF(I18>=4.21,"Strongly Agree",IF(I18>=3.41,"Agree",IF(I18>=2.61,"Neutral",IF(I18>=1.81,"Disagree","Strongly Disagree"))))) -> Strongly Agree
B19: Category mean — B. Functionality | I19: =IFERROR(AVERAGE(I14:I18),"") -> 4.28 | J19: =IF(I19="","",IF(I19>=4.21,"Strongly Agree",IF(I19>=3.41,"Agree",IF(I19>=2.61,"Neutral",IF(I19>=1.81,"Disagree","Strongly Disagree"))))) -> Strongly Agree
A21: C. Efficiency
A22: 1 | B22: The system reduces my idle time waiting for passengers. | C22: =COUNTIF('Driver Responses'!$S$6:$S$25,5) -> 5 | D22: =COUNTIF('Driver Responses'!$S$6:$S$25,4) -> 15 | E22: =COUNTIF('Driver Responses'!$S$6:$S$25,3) -> 0 | F22: =COUNTIF('Driver Responses'!$S$6:$S$25,2) -> 0 | G22: =COUNTIF('Driver Responses'!$S$6:$S$25,1) -> 0 | H22: =COUNT('Driver Responses'!$S$6:$S$25) -> 20 | I22: =IF(H22=0,"",(C22*5+D22*4+E22*3+F22*2+G22*1)/H22) -> 4.25 | J22: =IF(I22="","",IF(I22>=4.21,"Strongly Agree",IF(I22>=3.41,"Agree",IF(I22>=2.61,"Neutral",IF(I22>=1.81,"Disagree","Strongly Disagree"))))) -> Strongly Agree
A23: 2 | B23: Managing ride requests through the system is faster than the manual process. | C23: =COUNTIF('Driver Responses'!$T$6:$T$25,5) -> 7 | D23: =COUNTIF('Driver Responses'!$T$6:$T$25,4) -> 13 | E23: =COUNTIF('Driver Responses'!$T$6:$T$25,3) -> 0 | F23: =COUNTIF('Driver Responses'!$T$6:$T$25,2) -> 0 | G23: =COUNTIF('Driver Responses'!$T$6:$T$25,1) -> 0 | H23: =COUNT('Driver Responses'!$T$6:$T$25) -> 20 | I23: =IF(H23=0,"",(C23*5+D23*4+E23*3+F23*2+G23*1)/H23) -> 4.35 | J23: =IF(I23="","",IF(I23>=4.21,"Strongly Agree",IF(I23>=3.41,"Agree",IF(I23>=2.61,"Neutral",IF(I23>=1.81,"Disagree","Strongly Disagree"))))) -> Strongly Agree
A24: 3 | B24: The system responds quickly to my inputs and actions. | C24: =COUNTIF('Driver Responses'!$U$6:$U$25,5) -> 4 | D24: =COUNTIF('Driver Responses'!$U$6:$U$25,4) -> 15 | E24: =COUNTIF('Driver Responses'!$U$6:$U$25,3) -> 1 | F24: =COUNTIF('Driver Responses'!$U$6:$U$25,2) -> 0 | G24: =COUNTIF('Driver Responses'!$U$6:$U$25,1) -> 0 | H24: =COUNT('Driver Responses'!$U$6:$U$25) -> 20 | I24: =IF(H24=0,"",(C24*5+D24*4+E24*3+F24*2+G24*1)/H24) -> 4.15 | J24: =IF(I24="","",IF(I24>=4.21,"Strongly Agree",IF(I24>=3.41,"Agree",IF(I24>=2.61,"Neutral",IF(I24>=1.81,"Disagree","Strongly Disagree"))))) -> Agree
A25: 4 | B25: The system helps me serve more passengers throughout the day. | C25: =COUNTIF('Driver Responses'!$V$6:$V$25,5) -> 8 | D25: =COUNTIF('Driver Responses'!$V$6:$V$25,4) -> 11 | E25: =COUNTIF('Driver Responses'!$V$6:$V$25,3) -> 1 | F25: =COUNTIF('Driver Responses'!$V$6:$V$25,2) -> 0 | G25: =COUNTIF('Driver Responses'!$V$6:$V$25,1) -> 0 | H25: =COUNT('Driver Responses'!$V$6:$V$25) -> 20 | I25: =IF(H25=0,"",(C25*5+D25*4+E25*3+F25*2+G25*1)/H25) -> 4.35 | J25: =IF(I25="","",IF(I25>=4.21,"Strongly Agree",IF(I25>=3.41,"Agree",IF(I25>=2.61,"Neutral",IF(I25>=1.81,"Disagree","Strongly Disagree"))))) -> Strongly Agree
A26: 5 | B26: Overall, the system improves my daily work experience as a driver. | C26: =COUNTIF('Driver Responses'!$W$6:$W$25,5) -> 7 | D26: =COUNTIF('Driver Responses'!$W$6:$W$25,4) -> 12 | E26: =COUNTIF('Driver Responses'!$W$6:$W$25,3) -> 1 | F26: =COUNTIF('Driver Responses'!$W$6:$W$25,2) -> 0 | G26: =COUNTIF('Driver Responses'!$W$6:$W$25,1) -> 0 | H26: =COUNT('Driver Responses'!$W$6:$W$25) -> 20 | I26: =IF(H26=0,"",(C26*5+D26*4+E26*3+F26*2+G26*1)/H26) -> 4.3 | J26: =IF(I26="","",IF(I26>=4.21,"Strongly Agree",IF(I26>=3.41,"Agree",IF(I26>=2.61,"Neutral",IF(I26>=1.81,"Disagree","Strongly Disagree"))))) -> Strongly Agree
B27: Category mean — C. Efficiency | I27: =IFERROR(AVERAGE(I22:I26),"") -> 4.28 | J27: =IF(I27="","",IF(I27>=4.21,"Strongly Agree",IF(I27>=3.41,"Agree",IF(I27>=2.61,"Neutral",IF(I27>=1.81,"Disagree","Strongly Disagree"))))) -> Strongly Agree
A29: D. Reliability
A30: 1 | B30: The system works consistently without errors or crashes. | C30: =COUNTIF('Driver Responses'!$X$6:$X$25,5) -> 10 | D30: =COUNTIF('Driver Responses'!$X$6:$X$25,4) -> 10 | E30: =COUNTIF('Driver Responses'!$X$6:$X$25,3) -> 0 | F30: =COUNTIF('Driver Responses'!$X$6:$X$25,2) -> 0 | G30: =COUNTIF('Driver Responses'!$X$6:$X$25,1) -> 0 | H30: =COUNT('Driver Responses'!$X$6:$X$25) -> 20 | I30: =IF(H30=0,"",(C30*5+D30*4+E30*3+F30*2+G30*1)/H30) -> 4.5 | J30: =IF(I30="","",IF(I30>=4.21,"Strongly Agree",IF(I30>=3.41,"Agree",IF(I30>=2.61,"Neutral",IF(I30>=1.81,"Disagree","Strongly Disagree"))))) -> Strongly Agree
A31: 2 | B31: I can depend on the system to deliver ride requests accurately. | C31: =COUNTIF('Driver Responses'!$Y$6:$Y$25,5) -> 7 | D31: =COUNTIF('Driver Responses'!$Y$6:$Y$25,4) -> 13 | E31: =COUNTIF('Driver Responses'!$Y$6:$Y$25,3) -> 0 | F31: =COUNTIF('Driver Responses'!$Y$6:$Y$25,2) -> 0 | G31: =COUNTIF('Driver Responses'!$Y$6:$Y$25,1) -> 0 | H31: =COUNT('Driver Responses'!$Y$6:$Y$25) -> 20 | I31: =IF(H31=0,"",(C31*5+D31*4+E31*3+F31*2+G31*1)/H31) -> 4.35 | J31: =IF(I31="","",IF(I31>=4.21,"Strongly Agree",IF(I31>=3.41,"Agree",IF(I31>=2.61,"Neutral",IF(I31>=1.81,"Disagree","Strongly Disagree"))))) -> Strongly Agree
A32: 3 | B32: The system maintains accurate and up-to-date information. | C32: =COUNTIF('Driver Responses'!$Z$6:$Z$25,5) -> 6 | D32: =COUNTIF('Driver Responses'!$Z$6:$Z$25,4) -> 14 | E32: =COUNTIF('Driver Responses'!$Z$6:$Z$25,3) -> 0 | F32: =COUNTIF('Driver Responses'!$Z$6:$Z$25,2) -> 0 | G32: =COUNTIF('Driver Responses'!$Z$6:$Z$25,1) -> 0 | H32: =COUNT('Driver Responses'!$Z$6:$Z$25) -> 20 | I32: =IF(H32=0,"",(C32*5+D32*4+E32*3+F32*2+G32*1)/H32) -> 4.3 | J32: =IF(I32="","",IF(I32>=4.21,"Strongly Agree",IF(I32>=3.41,"Agree",IF(I32>=2.61,"Neutral",IF(I32>=1.81,"Disagree","Strongly Disagree"))))) -> Strongly Agree
A33: 4 | B33: The system performs well even during busy hours. | C33: =COUNTIF('Driver Responses'!$AA$6:$AA$25,5) -> 7 | D33: =COUNTIF('Driver Responses'!$AA$6:$AA$25,4) -> 12 | E33: =COUNTIF('Driver Responses'!$AA$6:$AA$25,3) -> 1 | F33: =COUNTIF('Driver Responses'!$AA$6:$AA$25,2) -> 0 | G33: =COUNTIF('Driver Responses'!$AA$6:$AA$25,1) -> 0 | H33: =COUNT('Driver Responses'!$AA$6:$AA$25) -> 20 | I33: =IF(H33=0,"",(C33*5+D33*4+E33*3+F33*2+G33*1)/H33) -> 4.3 | J33: =IF(I33="","",IF(I33>=4.21,"Strongly Agree",IF(I33>=3.41,"Agree",IF(I33>=2.61,"Neutral",IF(I33>=1.81,"Disagree","Strongly Disagree"))))) -> Strongly Agree
A34: 5 | B34: I trust the system to support my work as a registered driver. | C34: =COUNTIF('Driver Responses'!$AB$6:$AB$25,5) -> 9 | D34: =COUNTIF('Driver Responses'!$AB$6:$AB$25,4) -> 11 | E34: =COUNTIF('Driver Responses'!$AB$6:$AB$25,3) -> 0 | F34: =COUNTIF('Driver Responses'!$AB$6:$AB$25,2) -> 0 | G34: =COUNTIF('Driver Responses'!$AB$6:$AB$25,1) -> 0 | H34: =COUNT('Driver Responses'!$AB$6:$AB$25) -> 20 | I34: =IF(H34=0,"",(C34*5+D34*4+E34*3+F34*2+G34*1)/H34) -> 4.45 | J34: =IF(I34="","",IF(I34>=4.21,"Strongly Agree",IF(I34>=3.41,"Agree",IF(I34>=2.61,"Neutral",IF(I34>=1.81,"Disagree","Strongly Disagree"))))) -> Strongly Agree
B35: Category mean — D. Reliability | I35: =IFERROR(AVERAGE(I30:I34),"") -> 4.38 | J35: =IF(I35="","",IF(I35>=4.21,"Strongly Agree",IF(I35>=3.41,"Agree",IF(I35>=2.61,"Neutral",IF(I35>=1.81,"Disagree","Strongly Disagree"))))) -> Strongly Agree
B37: OVERALL WEIGHTED MEAN | I37: =IFERROR(AVERAGE(I11,I19,I27,I35),"") -> 4.285 | J37: =IF(I37="","",IF(I37>=4.21,"Strongly Agree",IF(I37>=3.41,"Agree",IF(I37>=2.61,"Neutral",IF(I37>=1.81,"Disagree","Strongly Disagree"))))) -> Strongly Agree
B39: The overall mean averages the category means, so each characteristic counts equally regardless of how many items it has. Average column I of the items instead if your statistician wants every item weighted equally.

Sheet Tally - Admin
A1: Tally - Admin
A2: Every figure is a formula reading 'Admin Responses' rows 6-205. Nothing on this sheet needs typing.
A4: # | B4: Indicator | C4: 5 | D4: 4 | E4: 3 | F4: 2 | G4: 1 | H4: N | I4: Weighted Mean | J4: Interpretation
A5: A. Functional Suitability
A6: 1 | B6: I can approve driver applications. | C6: =COUNTIF('Admin Responses'!$E$6:$E$6,5) -> 1 | D6: =COUNTIF('Admin Responses'!$E$6:$E$6,4) -> 0 | E6: =COUNTIF('Admin Responses'!$E$6:$E$6,3) -> 0 | F6: =COUNTIF('Admin Responses'!$E$6:$E$6,2) -> 0 | G6: =COUNTIF('Admin Responses'!$E$6:$E$6,1) -> 0 | H6: =COUNT('Admin Responses'!$E$6:$E$6) -> 1 | I6: =IF(H6=0,"",(C6*5+D6*4+E6*3+F6*2+G6*1)/H6) -> 5 | J6: =IF(I6="","",IF(I6>=4.21,"Strongly Agree",IF(I6>=3.41,"Agree",IF(I6>=2.61,"Neutral",IF(I6>=1.81,"Disagree","Strongly Disagree"))))) -> Strongly Agree
A7: 2 | B7: I can monitor ride activities. | C7: =COUNTIF('Admin Responses'!$F$6:$F$6,5) -> 1 | D7: =COUNTIF('Admin Responses'!$F$6:$F$6,4) -> 0 | E7: =COUNTIF('Admin Responses'!$F$6:$F$6,3) -> 0 | F7: =COUNTIF('Admin Responses'!$F$6:$F$6,2) -> 0 | G7: =COUNTIF('Admin Responses'!$F$6:$F$6,1) -> 0 | H7: =COUNT('Admin Responses'!$F$6:$F$6) -> 1 | I7: =IF(H7=0,"",(C7*5+D7*4+E7*3+F7*2+G7*1)/H7) -> 5 | J7: =IF(I7="","",IF(I7>=4.21,"Strongly Agree",IF(I7>=3.41,"Agree",IF(I7>=2.61,"Neutral",IF(I7>=1.81,"Disagree","Strongly Disagree"))))) -> Strongly Agree
A8: 3 | B8: I can manage user accounts. | C8: =COUNTIF('Admin Responses'!$G$6:$G$6,5) -> 1 | D8: =COUNTIF('Admin Responses'!$G$6:$G$6,4) -> 0 | E8: =COUNTIF('Admin Responses'!$G$6:$G$6,3) -> 0 | F8: =COUNTIF('Admin Responses'!$G$6:$G$6,2) -> 0 | G8: =COUNTIF('Admin Responses'!$G$6:$G$6,1) -> 0 | H8: =COUNT('Admin Responses'!$G$6:$G$6) -> 1 | I8: =IF(H8=0,"",(C8*5+D8*4+E8*3+F8*2+G8*1)/H8) -> 5 | J8: =IF(I8="","",IF(I8>=4.21,"Strongly Agree",IF(I8>=3.41,"Agree",IF(I8>=2.61,"Neutral",IF(I8>=1.81,"Disagree","Strongly Disagree"))))) -> Strongly Agree
B9: Category mean — A. Functional Suitability | I9: =IFERROR(AVERAGE(I6:I8),"") -> 5 | J9: =IF(I9="","",IF(I9>=4.21,"Strongly Agree",IF(I9>=3.41,"Agree",IF(I9>=2.61,"Neutral",IF(I9>=1.81,"Disagree","Strongly Disagree"))))) -> Strongly Agree
A11: B. Usability
A12: 1 | B12: The dashboard is easy to use. | C12: =COUNTIF('Admin Responses'!$H$6:$H$6,5) -> 1 | D12: =COUNTIF('Admin Responses'!$H$6:$H$6,4) -> 0 | E12: =COUNTIF('Admin Responses'!$H$6:$H$6,3) -> 0 | F12: =COUNTIF('Admin Responses'!$H$6:$H$6,2) -> 0 | G12: =COUNTIF('Admin Responses'!$H$6:$H$6,1) -> 0 | H12: =COUNT('Admin Responses'!$H$6:$H$6) -> 1 | I12: =IF(H12=0,"",(C12*5+D12*4+E12*3+F12*2+G12*1)/H12) -> 5 | J12: =IF(I12="","",IF(I12>=4.21,"Strongly Agree",IF(I12>=3.41,"Agree",IF(I12>=2.61,"Neutral",IF(I12>=1.81,"Disagree","Strongly Disagree"))))) -> Strongly Agree
A13: 2 | B13: Reports are easy to generate. | C13: =COUNTIF('Admin Responses'!$I$6:$I$6,5) -> 1 | D13: =COUNTIF('Admin Responses'!$I$6:$I$6,4) -> 0 | E13: =COUNTIF('Admin Responses'!$I$6:$I$6,3) -> 0 | F13: =COUNTIF('Admin Responses'!$I$6:$I$6,2) -> 0 | G13: =COUNTIF('Admin Responses'!$I$6:$I$6,1) -> 0 | H13: =COUNT('Admin Responses'!$I$6:$I$6) -> 1 | I13: =IF(H13=0,"",(C13*5+D13*4+E13*3+F13*2+G13*1)/H13) -> 5 | J13: =IF(I13="","",IF(I13>=4.21,"Strongly Agree",IF(I13>=3.41,"Agree",IF(I13>=2.61,"Neutral",IF(I13>=1.81,"Disagree","Strongly Disagree"))))) -> Strongly Agree
B14: Category mean — B. Usability | I14: =IFERROR(AVERAGE(I12:I13),"") -> 5 | J14: =IF(I14="","",IF(I14>=4.21,"Strongly Agree",IF(I14>=3.41,"Agree",IF(I14>=2.61,"Neutral",IF(I14>=1.81,"Disagree","Strongly Disagree"))))) -> Strongly Agree
A16: C. Reliability
A17: 1 | B17: Records are accurate. | C17: =COUNTIF('Admin Responses'!$J$6:$J$6,5) -> 0 | D17: =COUNTIF('Admin Responses'!$J$6:$J$6,4) -> 1 | E17: =COUNTIF('Admin Responses'!$J$6:$J$6,3) -> 0 | F17: =COUNTIF('Admin Responses'!$J$6:$J$6,2) -> 0 | G17: =COUNTIF('Admin Responses'!$J$6:$J$6,1) -> 0 | H17: =COUNT('Admin Responses'!$J$6:$J$6) -> 1 | I17: =IF(H17=0,"",(C17*5+D17*4+E17*3+F17*2+G17*1)/H17) -> 4 | J17: =IF(I17="","",IF(I17>=4.21,"Strongly Agree",IF(I17>=3.41,"Agree",IF(I17>=2.61,"Neutral",IF(I17>=1.81,"Disagree","Strongly Disagree"))))) -> Agree
A18: 2 | B18: Data updates correctly. | C18: =COUNTIF('Admin Responses'!$K$6:$K$6,5) -> 0 | D18: =COUNTIF('Admin Responses'!$K$6:$K$6,4) -> 1 | E18: =COUNTIF('Admin Responses'!$K$6:$K$6,3) -> 0 | F18: =COUNTIF('Admin Responses'!$K$6:$K$6,2) -> 0 | G18: =COUNTIF('Admin Responses'!$K$6:$K$6,1) -> 0 | H18: =COUNT('Admin Responses'!$K$6:$K$6) -> 1 | I18: =IF(H18=0,"",(C18*5+D18*4+E18*3+F18*2+G18*1)/H18) -> 4 | J18: =IF(I18="","",IF(I18>=4.21,"Strongly Agree",IF(I18>=3.41,"Agree",IF(I18>=2.61,"Neutral",IF(I18>=1.81,"Disagree","Strongly Disagree"))))) -> Agree
B19: Category mean — C. Reliability | I19: =IFERROR(AVERAGE(I17:I18),"") -> 4 | J19: =IF(I19="","",IF(I19>=4.21,"Strongly Agree",IF(I19>=3.41,"Agree",IF(I19>=2.61,"Neutral",IF(I19>=1.81,"Disagree","Strongly Disagree"))))) -> Agree
B21: OVERALL WEIGHTED MEAN | I21: =IFERROR(AVERAGE(I9,I14,I19),"") -> 4.6666667 | J21: =IF(I21="","",IF(I21>=4.21,"Strongly Agree",IF(I21>=3.41,"Agree",IF(I21>=2.61,"Neutral",IF(I21>=1.81,"Disagree","Strongly Disagree"))))) -> Strongly Agree
B23: The overall mean averages the category means, so each characteristic counts equally regardless of how many items it has. Average column I of the items instead if your statistician wants every item weighted equally.
