Workbook

Sheet Instructions
B2: TrikRide — Survey Tally Workbook
B3: A Smart Tricycle Ride and Driver Onboarding System for Talibon Polytechnic College
B4: Transcribed from Mumar_Capstone_Revised_2.docx. Every count and mean on the tally sheets is a formula — type the raw responses and the tallies fill themselves in.
B6: How to use it
B7: 1. | C7: Enter one questionnaire per row on the matching Responses sheet. Passengers, drivers and the administrator each have their own sheet, because they answered different instruments.
B8: 2. | C8: Put a whole number 1 to 5 in each item column — the weight the respondent ticked. Leave a cell blank if they skipped that item; blanks are excluded from that item's mean rather than counted as zero.
B9: 3. | C9: Row 5 of each Responses sheet is a worked example, shaded yellow. Delete that row before you tally — it is outside the formula range, so it will not affect the results either way.
B10: 4. | C10: Read the results on the three Tally sheets. Nothing there needs typing.
B11: 5. | C11: Type the written answers on the Open-Ended sheet, one row per respondent.
B13: Rating scale, as printed on the questionnaire
B14: Weight | C14: Weighted Mean | D14: Response
B15: 5 | C15: 4.21 - 5.00 | D15: Strongly Agree
B16: 4 | C16: 3.41 - 4.20 | D16: Agree
B17: 3 | C17: 2.61 - 3.40 | D17: Neutral
B18: 2 | C18: 1.81 - 2.60 | D18: Disagree
B19: 1 | C19: 1.00 - 1.80 | D19: Strongly Disagree
B21: What is in this workbook
B22: Passenger Responses | C22: Profile + 34 items (Part II, A to F)
B23: Driver Responses | C23: Profile + 20 items (the separate driver instrument)
B24: Admin Responses | C24: Profile + 7 items (Part III)
B25: Tally - Passenger | C25: Counts, weighted mean and interpretation per item
B26: Tally - Driver | C26: The same, for drivers
B27: Tally - Admin | C27: The same, for the administrator
B28: Open-Ended | C28: The written answers, verbatim
B30: One thing to fix before printing
B31: Part II, section B (Usability) lists "The system is easy to learn." twice — as item 1 and again as item 6. It is kept here exactly as printed so the sheet matches the paper, but asking the same question twice pulls that section's mean toward whatever respondents think of that one statement. Replace item 6 on the questionnaire and on the Passenger Responses and Tally - Passenger sheets, or delete it from all three.
B33: Source: Mumar_Capstone_Revised_2.docx, Survey Questionnaire (Parts I to IV) and the driver instrument that follows it.

Sheet Passenger Responses
A1: Passenger Responses
A2: One row per student/passenger respondent. Item columns take a whole number 1-5; the full statement is printed sideways above each one.
I3: The ride booking feature works as expected. | J3: I receive timely notifications about my ride status. | K3: The system accurately matches me with an available driver. | L3: I can view the status of my booking in real time. | M3: The system performs all its intended functions correctly. | N3: The fare displayed is accurate. | O3: Driver information is correctly displayed. | P3: Ride history is properly recorded. | Q3: The system is easy to learn. | R3: The menus are easy to understand. | S3: Icons and buttons are properly labeled. | T3: The interface is visually appealing. | U3: I can complete my tasks without confusion. | V3: The system is easy to learn. | W3: The application loads quickly. | X3: Booking requests are processed immediately. | Y3: Notifications arrive without delay. | Z3: The system performs smoothly. | AA3: The application consumes minimal mobile resources. | AB3: The system recovers properly after connection interruptions. | AC3: I can depend on the system to connect me with a driver when needed. | AD3: The system maintains accurate and up-to-date information. | AE3: The system performs well even during peak hours. | AF3: I trust the system to provide a safe and reliable ride booking experience. | AG3: I feel that my personal information is protected. | AH3: The login process is secure. | AI3: Only authorized users can access their accounts. | AJ3: Driver information is securely stored. | AK3: I trust the system to protect my data. | AL3: I am satisfied with the overall performance of the system. | AM3: I would recommend this system to others. | AN3: I intend to continue using the system. | AO3: The system meets my expectations. | AP3: Overall, I rate the system as effective.
A4: Respondent No. | B4: Name (optional) | C4: Age | D4: Gender | E4: Course | F4: Year Level | G4: Frequency of using tricycles | H4: Average rides per week | I4: A1 | J4: A2 | K4: A3 | L4: A4 | M4: A5 | N4: A6 | O4: A7 | P4: A8 | Q4: B1 | R4: B2 | S4: B3 | T4: B4 | U4: B5 | V4: B6 | W4: C1 | X4: C2 | Y4: C3 | Z4: C4 | AA4: C5 | AB4: D1 | AC4: D2 | AD4: D3 | AE4: D4 | AF4: D5 | AG4: E1 | AH4: E2 | AI4: E3 | AJ4: E4 | AK4: E5 | AL4: F1 | AM4: F2 | AN4: F3 | AO4: F4 | AP4: F5
A5: EXAMPLE - delete | B5: Juan Dela Cruz | C5: 20 | D5: Female | E5: BSIS | F5: 3rd Year | G5: Often | H5: 6-10 | I5: 5 | J5: 4 | K5: 5 | L5: 4 | M5: 5 | N5: 5 | O5: 4 | P5: 5 | Q5: 4 | R5: 5 | S5: 5 | T5: 4 | U5: 5 | V5: 4 | W5: 5 | X5: 5 | Y5: 4 | Z5: 5 | AA5: 4 | AB5: 5 | AC5: 5 | AD5: 4 | AE5: 5 | AF5: 4 | AG5: 5 | AH5: 5 | AI5: 4 | AJ5: 5 | AK5: 4 | AL5: 5 | AM5: 5 | AN5: 4 | AO5: 5 | AP5: 4
A6: 1
A7: 2
A8: 3
A9: 4
A10: 5
A11: 6
A12: 7
A13: 8
A14: 9
A15: 10
A16: 11
A17: 12
... A205: 200

Sheet Driver Responses
A1: Driver Responses
A2: One row per tricycle driver respondent, using the driver instrument.
I3: The system is easy to navigate and use. | J3: The interface is clean and visually understandable. | K3: I was able to register and set up my account without difficulty. | L3: The instructions and labels in the system are clear and easy to understand. | M3: I can comfortably use the system without any technical assistance. | N3: The ride request feature works as expected. | O3: I receive timely notifications about incoming ride requests. | P3: The system accurately shows my availability status to passengers. | Q3: I can manage and track my rides through the system in real time. | R3: The system performs all its intended functions correctly. | S3: The system reduces my idle time waiting for passengers. | T3: Managing ride requests through the system is faster than the manual process. | U3: The system responds quickly to my inputs and actions. | V3: The system helps me serve more passengers throughout the day. | W3: Overall, the system improves my daily work experience as a driver. | X3: The system works consistently without errors or crashes. | Y3: I can depend on the system to deliver ride requests accurately. | Z3: The system maintains accurate and up-to-date information. | AA3: The system performs well even during busy hours. | AB3: I trust the system to support my work as a registered driver.
A4: Respondent No. | B4: Name (optional) | C4: Age | D4: Gender | E4: Years of driving experience | F4: Owns smartphone | G4: Internet access | H4: Average trips per day | I4: A1 | J4: A2 | K4: A3 | L4: A4 | M4: A5 | N4: B1 | O4: B2 | P4: B3 | Q4: B4 | R4: B5 | S4: C1 | T4: C2 | U4: C3 | V4: C4 | W4: C5 | X4: D1 | Y4: D2 | Z4: D3 | AA4: D4 | AB4: D5
A5: EXAMPLE - delete | B5: Pedro Santos | C5: 41 | D5: Male | E5: 4-6 years | F5: Yes | G5: Yes | H5: 11-15 | I5: 5 | J5: 4 | K5: 5 | L5: 4 | M5: 5 | N5: 5 | O5: 4 | P5: 5 | Q5: 4 | R5: 5 | S5: 5 | T5: 4 | U5: 5 | V5: 4 | W5: 5 | X5: 5 | Y5: 4 | Z5: 5 | AA5: 4 | AB5: 5
A6: 1
A7: 2
A8: 3
A9: 4
A10: 5
A11: 6
A12: 7
A13: 8
A14: 9
A15: 10
A16: 11
A17: 12
... A205: 200

Sheet Admin Responses
A1: Admin Responses
A2: Part III, answered by the system administrator.
E3: I can approve driver applications. | F3: I can monitor ride activities. | G3: I can manage user accounts. | H3: The dashboard is easy to use. | I3: Reports are easy to generate. | J3: Records are accurate. | K3: Data updates correctly.
A4: Respondent No. | B4: Name (optional) | C4: Age | D4: Gender | E4: A1 | F4: A2 | G4: A3 | H4: B1 | I4: B2 | J4: C1 | K4: C2
A5: EXAMPLE - delete | B5: Maria Reyes | C5: 33 | D5: Female | E5: 5 | F5: 4 | G5: 5 | H5: 4 | I5: 5 | J5: 5 | K5: 4
A6: 1
A7: 2
A8: 3
A9: 4
A10: 5
A11: 6
A12: 7
A13: 8
A14: 9
A15: 10
A16: 11
A17: 12
... A205: 200

Sheet Tally - Passenger
A1: Tally - Passenger
A2: Every figure is a formula reading 'Passenger Responses' rows 6-205. Nothing on this sheet needs typing.
A4: # | B4: Indicator | C4: 5 | D4: 4 | E4: 3 | F4: 2 | G4: 1 | H4: N | I4: Weighted Mean | J4: Interpretation
A5: A. Functional Suitability
A6: 1 | B6: The ride booking feature works as expected. | C6: =COUNTIF('Passenger Responses'!$I$6:$I$205,5) | D6: =COUNTIF('Passenger Responses'!$I$6:$I$205,4) | E6: =COUNTIF('Passenger Responses'!$I$6:$I$205,3) | F6: =COUNTIF('Passenger Responses'!$I$6:$I$205,2) | G6: =COUNTIF('Passenger Responses'!$I$6:$I$205,1) | H6: =COUNT('Passenger Responses'!$I$6:$I$205) | I6: =IF(H6=0,"",(C6*5+D6*4+E6*3+F6*2+G6*1)/H6) | J6: =IF(I6="","",IF(I6>=4.21,"Strongly Agree",IF(I6>=3.41,"Agree",IF(I6>=2.61,"Neutral",IF(I6>=1.81,"Disagree","Strongly Disagree")))))
A7: 2 | B7: I receive timely notifications about my ride status. | C7: =COUNTIF('Passenger Responses'!$J$6:$J$205,5) | D7: =COUNTIF('Passenger Responses'!$J$6:$J$205,4) | E7: =COUNTIF('Passenger Responses'!$J$6:$J$205,3) | F7: =COUNTIF('Passenger Responses'!$J$6:$J$205,2) | G7: =COUNTIF('Passenger Responses'!$J$6:$J$205,1) | H7: =COUNT('Passenger Responses'!$J$6:$J$205) | I7: =IF(H7=0,"",(C7*5+D7*4+E7*3+F7*2+G7*1)/H7) | J7: =IF(I7="","",IF(I7>=4.21,"Strongly Agree",IF(I7>=3.41,"Agree",IF(I7>=2.61,"Neutral",IF(I7>=1.81,"Disagree","Strongly Disagree")))))
A8: 3 | B8: The system accurately matches me with an available driver. | C8: =COUNTIF('Passenger Responses'!$K$6:$K$205,5) | D8: =COUNTIF('Passenger Responses'!$K$6:$K$205,4) | E8: =COUNTIF('Passenger Responses'!$K$6:$K$205,3) | F8: =COUNTIF('Passenger Responses'!$K$6:$K$205,2) | G8: =COUNTIF('Passenger Responses'!$K$6:$K$205,1) | H8: =COUNT('Passenger Responses'!$K$6:$K$205) | I8: =IF(H8=0,"",(C8*5+D8*4+E8*3+F8*2+G8*1)/H8) | J8: =IF(I8="","",IF(I8>=4.21,"Strongly Agree",IF(I8>=3.41,"Agree",IF(I8>=2.61,"Neutral",IF(I8>=1.81,"Disagree","Strongly Disagree")))))
A9: 4 | B9: I can view the status of my booking in real time. | C9: =COUNTIF('Passenger Responses'!$L$6:$L$205,5) | D9: =COUNTIF('Passenger Responses'!$L$6:$L$205,4) | E9: =COUNTIF('Passenger Responses'!$L$6:$L$205,3) | F9: =COUNTIF('Passenger Responses'!$L$6:$L$205,2) | G9: =COUNTIF('Passenger Responses'!$L$6:$L$205,1) | H9: =COUNT('Passenger Responses'!$L$6:$L$205) | I9: =IF(H9=0,"",(C9*5+D9*4+E9*3+F9*2+G9*1)/H9) | J9: =IF(I9="","",IF(I9>=4.21,"Strongly Agree",IF(I9>=3.41,"Agree",IF(I9>=2.61,"Neutral",IF(I9>=1.81,"Disagree","Strongly Disagree")))))
A10: 5 | B10: The system performs all its intended functions correctly. | C10: =COUNTIF('Passenger Responses'!$M$6:$M$205,5) | D10: =COUNTIF('Passenger Responses'!$M$6:$M$205,4) | E10: =COUNTIF('Passenger Responses'!$M$6:$M$205,3) | F10: =COUNTIF('Passenger Responses'!$M$6:$M$205,2) | G10: =COUNTIF('Passenger Responses'!$M$6:$M$205,1) | H10: =COUNT('Passenger Responses'!$M$6:$M$205) | I10: =IF(H10=0,"",(C10*5+D10*4+E10*3+F10*2+G10*1)/H10) | J10: =IF(I10="","",IF(I10>=4.21,"Strongly Agree",IF(I10>=3.41,"Agree",IF(I10>=2.61,"Neutral",IF(I10>=1.81,"Disagree","Strongly Disagree")))))
A11: 6 | B11: The fare displayed is accurate. | C11: =COUNTIF('Passenger Responses'!$N$6:$N$205,5) | D11: =COUNTIF('Passenger Responses'!$N$6:$N$205,4) | E11: =COUNTIF('Passenger Responses'!$N$6:$N$205,3) | F11: =COUNTIF('Passenger Responses'!$N$6:$N$205,2) | G11: =COUNTIF('Passenger Responses'!$N$6:$N$205,1) | H11: =COUNT('Passenger Responses'!$N$6:$N$205) | I11: =IF(H11=0,"",(C11*5+D11*4+E11*3+F11*2+G11*1)/H11) | J11: =IF(I11="","",IF(I11>=4.21,"Strongly Agree",IF(I11>=3.41,"Agree",IF(I11>=2.61,"Neutral",IF(I11>=1.81,"Disagree","Strongly Disagree")))))
A12: 7 | B12: Driver information is correctly displayed. | C12: =COUNTIF('Passenger Responses'!$O$6:$O$205,5) | D12: =COUNTIF('Passenger Responses'!$O$6:$O$205,4) | E12: =COUNTIF('Passenger Responses'!$O$6:$O$205,3) | F12: =COUNTIF('Passenger Responses'!$O$6:$O$205,2) | G12: =COUNTIF('Passenger Responses'!$O$6:$O$205,1) | H12: =COUNT('Passenger Responses'!$O$6:$O$205) | I12: =IF(H12=0,"",(C12*5+D12*4+E12*3+F12*2+G12*1)/H12) | J12: =IF(I12="","",IF(I12>=4.21,"Strongly Agree",IF(I12>=3.41,"Agree",IF(I12>=2.61,"Neutral",IF(I12>=1.81,"Disagree","Strongly Disagree")))))
A13: 8 | B13: Ride history is properly recorded. | C13: =COUNTIF('Passenger Responses'!$P$6:$P$205,5) | D13: =COUNTIF('Passenger Responses'!$P$6:$P$205,4) | E13: =COUNTIF('Passenger Responses'!$P$6:$P$205,3) | F13: =COUNTIF('Passenger Responses'!$P$6:$P$205,2) | G13: =COUNTIF('Passenger Responses'!$P$6:$P$205,1) | H13: =COUNT('Passenger Responses'!$P$6:$P$205) | I13: =IF(H13=0,"",(C13*5+D13*4+E13*3+F13*2+G13*1)/H13) | J13: =IF(I13="","",IF(I13>=4.21,"Strongly Agree",IF(I13>=3.41,"Agree",IF(I13>=2.61,"Neutral",IF(I13>=1.81,"Disagree","Strongly Disagree")))))
B14: Category mean — A. Functional Suitability | I14: =IFERROR(AVERAGE(I6:I13),"") | J14: =IF(I14="","",IF(I14>=4.21,"Strongly Agree",IF(I14>=3.41,"Agree",IF(I14>=2.61,"Neutral",IF(I14>=1.81,"Disagree","Strongly Disagree")))))
A16: B. Usability
A17: 1 | B17: The system is easy to learn. | C17: =COUNTIF('Passenger Responses'!$Q$6:$Q$205,5) | D17: =COUNTIF('Passenger Responses'!$Q$6:$Q$205,4) | E17: =COUNTIF('Passenger Responses'!$Q$6:$Q$205,3) | F17: =COUNTIF('Passenger Responses'!$Q$6:$Q$205,2) | G17: =COUNTIF('Passenger Responses'!$Q$6:$Q$205,1) | H17: =COUNT('Passenger Responses'!$Q$6:$Q$205) | I17: =IF(H17=0,"",(C17*5+D17*4+E17*3+F17*2+G17*1)/H17) | J17: =IF(I17="","",IF(I17>=4.21,"Strongly Agree",IF(I17>=3.41,"Agree",IF(I17>=2.61,"Neutral",IF(I17>=1.81,"Disagree","Strongly Disagree")))))
A18: 2 | B18: The menus are easy to understand. | C18: =COUNTIF('Passenger Responses'!$R$6:$R$205,5) | D18: =COUNTIF('Passenger Responses'!$R$6:$R$205,4) | E18: =COUNTIF('Passenger Responses'!$R$6:$R$205,3) | F18: =COUNTIF('Passenger Responses'!$R$6:$R$205,2) | G18: =COUNTIF('Passenger Responses'!$R$6:$R$205,1) | H18: =COUNT('Passenger Responses'!$R$6:$R$205) | I18: =IF(H18=0,"",(C18*5+D18*4+E18*3+F18*2+G18*1)/H18) | J18: =IF(I18="","",IF(I18>=4.21,"Strongly Agree",IF(I18>=3.41,"Agree",IF(I18>=2.61,"Neutral",IF(I18>=1.81,"Disagree","Strongly Disagree")))))
A19: 3 | B19: Icons and buttons are properly labeled. | C19: =COUNTIF('Passenger Responses'!$S$6:$S$205,5) | D19: =COUNTIF('Passenger Responses'!$S$6:$S$205,4) | E19: =COUNTIF('Passenger Responses'!$S$6:$S$205,3) | F19: =COUNTIF('Passenger Responses'!$S$6:$S$205,2) | G19: =COUNTIF('Passenger Responses'!$S$6:$S$205,1) | H19: =COUNT('Passenger Responses'!$S$6:$S$205) | I19: =IF(H19=0,"",(C19*5+D19*4+E19*3+F19*2+G19*1)/H19) | J19: =IF(I19="","",IF(I19>=4.21,"Strongly Agree",IF(I19>=3.41,"Agree",IF(I19>=2.61,"Neutral",IF(I19>=1.81,"Disagree","Strongly Disagree")))))
A20: 4 | B20: The interface is visually appealing. | C20: =COUNTIF('Passenger Responses'!$T$6:$T$205,5) | D20: =COUNTIF('Passenger Responses'!$T$6:$T$205,4) | E20: =COUNTIF('Passenger Responses'!$T$6:$T$205,3) | F20: =COUNTIF('Passenger Responses'!$T$6:$T$205,2) | G20: =COUNTIF('Passenger Responses'!$T$6:$T$205,1) | H20: =COUNT('Passenger Responses'!$T$6:$T$205) | I20: =IF(H20=0,"",(C20*5+D20*4+E20*3+F20*2+G20*1)/H20) | J20: =IF(I20="","",IF(I20>=4.21,"Strongly Agree",IF(I20>=3.41,"Agree",IF(I20>=2.61,"Neutral",IF(I20>=1.81,"Disagree","Strongly Disagree")))))
A21: 5 | B21: I can complete my tasks without confusion. | C21: =COUNTIF('Passenger Responses'!$U$6:$U$205,5) | D21: =COUNTIF('Passenger Responses'!$U$6:$U$205,4) | E21: =COUNTIF('Passenger Responses'!$U$6:$U$205,3) | F21: =COUNTIF('Passenger Responses'!$U$6:$U$205,2) | G21: =COUNTIF('Passenger Responses'!$U$6:$U$205,1) | H21: =COUNT('Passenger Responses'!$U$6:$U$205) | I21: =IF(H21=0,"",(C21*5+D21*4+E21*3+F21*2+G21*1)/H21) | J21: =IF(I21="","",IF(I21>=4.21,"Strongly Agree",IF(I21>=3.41,"Agree",IF(I21>=2.61,"Neutral",IF(I21>=1.81,"Disagree","Strongly Disagree")))))
A22: 6 | B22: The system is easy to learn. | C22: =COUNTIF('Passenger Responses'!$V$6:$V$205,5) | D22: =COUNTIF('Passenger Responses'!$V$6:$V$205,4) | E22: =COUNTIF('Passenger Responses'!$V$6:$V$205,3) | F22: =COUNTIF('Passenger Responses'!$V$6:$V$205,2) | G22: =COUNTIF('Passenger Responses'!$V$6:$V$205,1) | H22: =COUNT('Passenger Responses'!$V$6:$V$205) | I22: =IF(H22=0,"",(C22*5+D22*4+E22*3+F22*2+G22*1)/H22) | J22: =IF(I22="","",IF(I22>=4.21,"Strongly Agree",IF(I22>=3.41,"Agree",IF(I22>=2.61,"Neutral",IF(I22>=1.81,"Disagree","Strongly Disagree")))))
B23: Category mean — B. Usability | I23: =IFERROR(AVERAGE(I17:I22),"") | J23: =IF(I23="","",IF(I23>=4.21,"Strongly Agree",IF(I23>=3.41,"Agree",IF(I23>=2.61,"Neutral",IF(I23>=1.81,"Disagree","Strongly Disagree")))))
A25: C. Efficiency
A26: 1 | B26: The application loads quickly. | C26: =COUNTIF('Passenger Responses'!$W$6:$W$205,5) | D26: =COUNTIF('Passenger Responses'!$W$6:$W$205,4) | E26: =COUNTIF('Passenger Responses'!$W$6:$W$205,3) | F26: =COUNTIF('Passenger Responses'!$W$6:$W$205,2) | G26: =COUNTIF('Passenger Responses'!$W$6:$W$205,1) | H26: =COUNT('Passenger Responses'!$W$6:$W$205) | I26: =IF(H26=0,"",(C26*5+D26*4+E26*3+F26*2+G26*1)/H26) | J26: =IF(I26="","",IF(I26>=4.21,"Strongly Agree",IF(I26>=3.41,"Agree",IF(I26>=2.61,"Neutral",IF(I26>=1.81,"Disagree","Strongly Disagree")))))
A27: 2 | B27: Booking requests are processed immediately. | C27: =COUNTIF('Passenger Responses'!$X$6:$X$205,5) | D27: =COUNTIF('Passenger Responses'!$X$6:$X$205,4) | E27: =COUNTIF('Passenger Responses'!$X$6:$X$205,3) | F27: =COUNTIF('Passenger Responses'!$X$6:$X$205,2) | G27: =COUNTIF('Passenger Responses'!$X$6:$X$205,1) | H27: =COUNT('Passenger Responses'!$X$6:$X$205) | I27: =IF(H27=0,"",(C27*5+D27*4+E27*3+F27*2+G27*1)/H27) | J27: =IF(I27="","",IF(I27>=4.21,"Strongly Agree",IF(I27>=3.41,"Agree",IF(I27>=2.61,"Neutral",IF(I27>=1.81,"Disagree","Strongly Disagree")))))
A28: 3 | B28: Notifications arrive without delay. | C28: =COUNTIF('Passenger Responses'!$Y$6:$Y$205,5) | D28: =COUNTIF('Passenger Responses'!$Y$6:$Y$205,4) | E28: =COUNTIF('Passenger Responses'!$Y$6:$Y$205,3) | F28: =COUNTIF('Passenger Responses'!$Y$6:$Y$205,2) | G28: =COUNTIF('Passenger Responses'!$Y$6:$Y$205,1) | H28: =COUNT('Passenger Responses'!$Y$6:$Y$205) | I28: =IF(H28=0,"",(C28*5+D28*4+E28*3+F28*2+G28*1)/H28) | J28: =IF(I28="","",IF(I28>=4.21,"Strongly Agree",IF(I28>=3.41,"Agree",IF(I28>=2.61,"Neutral",IF(I28>=1.81,"Disagree","Strongly Disagree")))))
A29: 4 | B29: The system performs smoothly. | C29: =COUNTIF('Passenger Responses'!$Z$6:$Z$205,5) | D29: =COUNTIF('Passenger Responses'!$Z$6:$Z$205,4) | E29: =COUNTIF('Passenger Responses'!$Z$6:$Z$205,3) | F29: =COUNTIF('Passenger Responses'!$Z$6:$Z$205,2) | G29: =COUNTIF('Passenger Responses'!$Z$6:$Z$205,1) | H29: =COUNT('Passenger Responses'!$Z$6:$Z$205) | I29: =IF(H29=0,"",(C29*5+D29*4+E29*3+F29*2+G29*1)/H29) | J29: =IF(I29="","",IF(I29>=4.21,"Strongly Agree",IF(I29>=3.41,"Agree",IF(I29>=2.61,"Neutral",IF(I29>=1.81,"Disagree","Strongly Disagree")))))
A30: 5 | B30: The application consumes minimal mobile resources. | C30: =COUNTIF('Passenger Responses'!$AA$6:$AA$205,5) | D30: =COUNTIF('Passenger Responses'!$AA$6:$AA$205,4) | E30: =COUNTIF('Passenger Responses'!$AA$6:$AA$205,3) | F30: =COUNTIF('Passenger Responses'!$AA$6:$AA$205,2) | G30: =COUNTIF('Passenger Responses'!$AA$6:$AA$205,1) | H30: =COUNT('Passenger Responses'!$AA$6:$AA$205) | I30: =IF(H30=0,"",(C30*5+D30*4+E30*3+F30*2+G30*1)/H30) | J30: =IF(I30="","",IF(I30>=4.21,"Strongly Agree",IF(I30>=3.41,"Agree",IF(I30>=2.61,"Neutral",IF(I30>=1.81,"Disagree","Strongly Disagree")))))
B31: Category mean — C. Efficiency | I31: =IFERROR(AVERAGE(I26:I30),"") | J31: =IF(I31="","",IF(I31>=4.21,"Strongly Agree",IF(I31>=3.41,"Agree",IF(I31>=2.61,"Neutral",IF(I31>=1.81,"Disagree","Strongly Disagree")))))
A33: D. Reliability
A34: 1 | B34: The system recovers properly after connection interruptions. | C34: =COUNTIF('Passenger Responses'!$AB$6:$AB$205,5) | D34: =COUNTIF('Passenger Responses'!$AB$6:$AB$205,4) | E34: =COUNTIF('Passenger Responses'!$AB$6:$AB$205,3) | F34: =COUNTIF('Passenger Responses'!$AB$6:$AB$205,2) | G34: =COUNTIF('Passenger Responses'!$AB$6:$AB$205,1) | H34: =COUNT('Passenger Responses'!$AB$6:$AB$205) | I34: =IF(H34=0,"",(C34*5+D34*4+E34*3+F34*2+G34*1)/H34) | J34: =IF(I34="","",IF(I34>=4.21,"Strongly Agree",IF(I34>=3.41,"Agree",IF(I34>=2.61,"Neutral",IF(I34>=1.81,"Disagree","Strongly Disagree")))))
A35: 2 | B35: I can depend on the system to connect me with a driver when needed. | C35: =COUNTIF('Passenger Responses'!$AC$6:$AC$205,5) | D35: =COUNTIF('Passenger Responses'!$AC$6:$AC$205,4) | E35: =COUNTIF('Passenger Responses'!$AC$6:$AC$205,3) | F35: =COUNTIF('Passenger Responses'!$AC$6:$AC$205,2) | G35: =COUNTIF('Passenger Responses'!$AC$6:$AC$205,1) | H35: =COUNT('Passenger Responses'!$AC$6:$AC$205) | I35: =IF(H35=0,"",(C35*5+D35*4+E35*3+F35*2+G35*1)/H35) | J35: =IF(I35="","",IF(I35>=4.21,"Strongly Agree",IF(I35>=3.41,"Agree",IF(I35>=2.61,"Neutral",IF(I35>=1.81,"Disagree","Strongly Disagree")))))
A36: 3 | B36: The system maintains accurate and up-to-date information. | C36: =COUNTIF('Passenger Responses'!$AD$6:$AD$205,5) | D36: =COUNTIF('Passenger Responses'!$AD$6:$AD$205,4) | E36: =COUNTIF('Passenger Responses'!$AD$6:$AD$205,3) | F36: =COUNTIF('Passenger Responses'!$AD$6:$AD$205,2) | G36: =COUNTIF('Passenger Responses'!$AD$6:$AD$205,1) | H36: =COUNT('Passenger Responses'!$AD$6:$AD$205) | I36: =IF(H36=0,"",(C36*5+D36*4+E36*3+F36*2+G36*1)/H36) | J36: =IF(I36="","",IF(I36>=4.21,"Strongly Agree",IF(I36>=3.41,"Agree",IF(I36>=2.61,"Neutral",IF(I36>=1.81,"Disagree","Strongly Disagree")))))
A37: 4 | B37: The system performs well even during peak hours. | C37: =COUNTIF('Passenger Responses'!$AE$6:$AE$205,5) | D37: =COUNTIF('Passenger Responses'!$AE$6:$AE$205,4) | E37: =COUNTIF('Passenger Responses'!$AE$6:$AE$205,3) | F37: =COUNTIF('Passenger Responses'!$AE$6:$AE$205,2) | G37: =COUNTIF('Passenger Responses'!$AE$6:$AE$205,1) | H37: =COUNT('Passenger Responses'!$AE$6:$AE$205) | I37: =IF(H37=0,"",(C37*5+D37*4+E37*3+F37*2+G37*1)/H37) | J37: =IF(I37="","",IF(I37>=4.21,"Strongly Agree",IF(I37>=3.41,"Agree",IF(I37>=2.61,"Neutral",IF(I37>=1.81,"Disagree","Strongly Disagree")))))
A38: 5 | B38: I trust the system to provide a safe and reliable ride booking experience. | C38: =COUNTIF('Passenger Responses'!$AF$6:$AF$205,5) | D38: =COUNTIF('Passenger Responses'!$AF$6:$AF$205,4) | E38: =COUNTIF('Passenger Responses'!$AF$6:$AF$205,3) | F38: =COUNTIF('Passenger Responses'!$AF$6:$AF$205,2) | G38: =COUNTIF('Passenger Responses'!$AF$6:$AF$205,1) | H38: =COUNT('Passenger Responses'!$AF$6:$AF$205) | I38: =IF(H38=0,"",(C38*5+D38*4+E38*3+F38*2+G38*1)/H38) | J38: =IF(I38="","",IF(I38>=4.21,"Strongly Agree",IF(I38>=3.41,"Agree",IF(I38>=2.61,"Neutral",IF(I38>=1.81,"Disagree","Strongly Disagree")))))
B39: Category mean — D. Reliability | I39: =IFERROR(AVERAGE(I34:I38),"") | J39: =IF(I39="","",IF(I39>=4.21,"Strongly Agree",IF(I39>=3.41,"Agree",IF(I39>=2.61,"Neutral",IF(I39>=1.81,"Disagree","Strongly Disagree")))))
A41: E. Security
A42: 1 | B42: I feel that my personal information is protected. | C42: =COUNTIF('Passenger Responses'!$AG$6:$AG$205,5) | D42: =COUNTIF('Passenger Responses'!$AG$6:$AG$205,4) | E42: =COUNTIF('Passenger Responses'!$AG$6:$AG$205,3) | F42: =COUNTIF('Passenger Responses'!$AG$6:$AG$205,2) | G42: =COUNTIF('Passenger Responses'!$AG$6:$AG$205,1) | H42: =COUNT('Passenger Responses'!$AG$6:$AG$205) | I42: =IF(H42=0,"",(C42*5+D42*4+E42*3+F42*2+G42*1)/H42) | J42: =IF(I42="","",IF(I42>=4.21,"Strongly Agree",IF(I42>=3.41,"Agree",IF(I42>=2.61,"Neutral",IF(I42>=1.81,"Disagree","Strongly Disagree")))))
A43: 2 | B43: The login process is secure. | C43: =COUNTIF('Passenger Responses'!$AH$6:$AH$205,5) | D43: =COUNTIF('Passenger Responses'!$AH$6:$AH$205,4) | E43: =COUNTIF('Passenger Responses'!$AH$6:$AH$205,3) | F43: =COUNTIF('Passenger Responses'!$AH$6:$AH$205,2) | G43: =COUNTIF('Passenger Responses'!$AH$6:$AH$205,1) | H43: =COUNT('Passenger Responses'!$AH$6:$AH$205) | I43: =IF(H43=0,"",(C43*5+D43*4+E43*3+F43*2+G43*1)/H43) | J43: =IF(I43="","",IF(I43>=4.21,"Strongly Agree",IF(I43>=3.41,"Agree",IF(I43>=2.61,"Neutral",IF(I43>=1.81,"Disagree","Strongly Disagree")))))
A44: 3 | B44: Only authorized users can access their accounts. | C44: =COUNTIF('Passenger Responses'!$AI$6:$AI$205,5) | D44: =COUNTIF('Passenger Responses'!$AI$6:$AI$205,4) | E44: =COUNTIF('Passenger Responses'!$AI$6:$AI$205,3) | F44: =COUNTIF('Passenger Responses'!$AI$6:$AI$205,2) | G44: =COUNTIF('Passenger Responses'!$AI$6:$AI$205,1) | H44: =COUNT('Passenger Responses'!$AI$6:$AI$205) | I44: =IF(H44=0,"",(C44*5+D44*4+E44*3+F44*2+G44*1)/H44) | J44: =IF(I44="","",IF(I44>=4.21,"Strongly Agree",IF(I44>=3.41,"Agree",IF(I44>=2.61,"Neutral",IF(I44>=1.81,"Disagree","Strongly Disagree")))))
A45: 4 | B45: Driver information is securely stored. | C45: =COUNTIF('Passenger Responses'!$AJ$6:$AJ$205,5) | D45: =COUNTIF('Passenger Responses'!$AJ$6:$AJ$205,4) | E45: =COUNTIF('Passenger Responses'!$AJ$6:$AJ$205,3) | F45: =COUNTIF('Passenger Responses'!$AJ$6:$AJ$205,2) | G45: =COUNTIF('Passenger Responses'!$AJ$6:$AJ$205,1) | H45: =COUNT('Passenger Responses'!$AJ$6:$AJ$205) | I45: =IF(H45=0,"",(C45*5+D45*4+E45*3+F45*2+G45*1)/H45) | J45: =IF(I45="","",IF(I45>=4.21,"Strongly Agree",IF(I45>=3.41,"Agree",IF(I45>=2.61,"Neutral",IF(I45>=1.81,"Disagree","Strongly Disagree")))))
...

Sheet Tally - Driver
A1: Tally - Driver
A2: Every figure is a formula reading 'Driver Responses' rows 6-205. Nothing on this sheet needs typing.
A4: # | B4: Indicator | C4: 5 | D4: 4 | E4: 3 | F4: 2 | G4: 1 | H4: N | I4: Weighted Mean | J4: Interpretation
A5: A. Usability
A6: 1 | B6: The system is easy to navigate and use. | C6: =COUNTIF('Driver Responses'!$I$6:$I$205,5) | D6: =COUNTIF('Driver Responses'!$I$6:$I$205,4) | E6: =COUNTIF('Driver Responses'!$I$6:$I$205,3) | F6: =COUNTIF('Driver Responses'!$I$6:$I$205,2) | G6: =COUNTIF('Driver Responses'!$I$6:$I$205,1) | H6: =COUNT('Driver Responses'!$I$6:$I$205) | I6: =IF(H6=0,"",(C6*5+D6*4+E6*3+F6*2+G6*1)/H6) | J6: =IF(I6="","",IF(I6>=4.21,"Strongly Agree",IF(I6>=3.41,"Agree",IF(I6>=2.61,"Neutral",IF(I6>=1.81,"Disagree","Strongly Disagree")))))
A7: 2 | B7: The interface is clean and visually understandable. | C7: =COUNTIF('Driver Responses'!$J$6:$J$205,5) | D7: =COUNTIF('Driver Responses'!$J$6:$J$205,4) | E7: =COUNTIF('Driver Responses'!$J$6:$J$205,3) | F7: =COUNTIF('Driver Responses'!$J$6:$J$205,2) | G7: =COUNTIF('Driver Responses'!$J$6:$J$205,1) | H7: =COUNT('Driver Responses'!$J$6:$J$205) | I7: =IF(H7=0,"",(C7*5+D7*4+E7*3+F7*2+G7*1)/H7) | J7: =IF(I7="","",IF(I7>=4.21,"Strongly Agree",IF(I7>=3.41,"Agree",IF(I7>=2.61,"Neutral",IF(I7>=1.81,"Disagree","Strongly Disagree")))))
A8: 3 | B8: I was able to register and set up my account without difficulty. | C8: =COUNTIF('Driver Responses'!$K$6:$K$205,5) | D8: =COUNTIF('Driver Responses'!$K$6:$K$205,4) | E8: =COUNTIF('Driver Responses'!$K$6:$K$205,3) | F8: =COUNTIF('Driver Responses'!$K$6:$K$205,2) | G8: =COUNTIF('Driver Responses'!$K$6:$K$205,1) | H8: =COUNT('Driver Responses'!$K$6:$K$205) | I8: =IF(H8=0,"",(C8*5+D8*4+E8*3+F8*2+G8*1)/H8) | J8: =IF(I8="","",IF(I8>=4.21,"Strongly Agree",IF(I8>=3.41,"Agree",IF(I8>=2.61,"Neutral",IF(I8>=1.81,"Disagree","Strongly Disagree")))))
A9: 4 | B9: The instructions and labels in the system are clear and easy to understand. | C9: =COUNTIF('Driver Responses'!$L$6:$L$205,5) | D9: =COUNTIF('Driver Responses'!$L$6:$L$205,4) | E9: =COUNTIF('Driver Responses'!$L$6:$L$205,3) | F9: =COUNTIF('Driver Responses'!$L$6:$L$205,2) | G9: =COUNTIF('Driver Responses'!$L$6:$L$205,1) | H9: =COUNT('Driver Responses'!$L$6:$L$205) | I9: =IF(H9=0,"",(C9*5+D9*4+E9*3+F9*2+G9*1)/H9) | J9: =IF(I9="","",IF(I9>=4.21,"Strongly Agree",IF(I9>=3.41,"Agree",IF(I9>=2.61,"Neutral",IF(I9>=1.81,"Disagree","Strongly Disagree")))))
A10: 5 | B10: I can comfortably use the system without any technical assistance. | C10: =COUNTIF('Driver Responses'!$M$6:$M$205,5) | D10: =COUNTIF('Driver Responses'!$M$6:$M$205,4) | E10: =COUNTIF('Driver Responses'!$M$6:$M$205,3) | F10: =COUNTIF('Driver Responses'!$M$6:$M$205,2) | G10: =COUNTIF('Driver Responses'!$M$6:$M$205,1) | H10: =COUNT('Driver Responses'!$M$6:$M$205) | I10: =IF(H10=0,"",(C10*5+D10*4+E10*3+F10*2+G10*1)/H10) | J10: =IF(I10="","",IF(I10>=4.21,"Strongly Agree",IF(I10>=3.41,"Agree",IF(I10>=2.61,"Neutral",IF(I10>=1.81,"Disagree","Strongly Disagree")))))
B11: Category mean — A. Usability | I11: =IFERROR(AVERAGE(I6:I10),"") | J11: =IF(I11="","",IF(I11>=4.21,"Strongly Agree",IF(I11>=3.41,"Agree",IF(I11>=2.61,"Neutral",IF(I11>=1.81,"Disagree","Strongly Disagree")))))
A13: B. Functionality
A14: 1 | B14: The ride request feature works as expected. | C14: =COUNTIF('Driver Responses'!$N$6:$N$205,5) | D14: =COUNTIF('Driver Responses'!$N$6:$N$205,4) | E14: =COUNTIF('Driver Responses'!$N$6:$N$205,3) | F14: =COUNTIF('Driver Responses'!$N$6:$N$205,2) | G14: =COUNTIF('Driver Responses'!$N$6:$N$205,1) | H14: =COUNT('Driver Responses'!$N$6:$N$205) | I14: =IF(H14=0,"",(C14*5+D14*4+E14*3+F14*2+G14*1)/H14) | J14: =IF(I14="","",IF(I14>=4.21,"Strongly Agree",IF(I14>=3.41,"Agree",IF(I14>=2.61,"Neutral",IF(I14>=1.81,"Disagree","Strongly Disagree")))))
A15: 2 | B15: I receive timely notifications about incoming ride requests. | C15: =COUNTIF('Driver Responses'!$O$6:$O$205,5) | D15: =COUNTIF('Driver Responses'!$O$6:$O$205,4) | E15: =COUNTIF('Driver Responses'!$O$6:$O$205,3) | F15: =COUNTIF('Driver Responses'!$O$6:$O$205,2) | G15: =COUNTIF('Driver Responses'!$O$6:$O$205,1) | H15: =COUNT('Driver Responses'!$O$6:$O$205) | I15: =IF(H15=0,"",(C15*5+D15*4+E15*3+F15*2+G15*1)/H15) | J15: =IF(I15="","",IF(I15>=4.21,"Strongly Agree",IF(I15>=3.41,"Agree",IF(I15>=2.61,"Neutral",IF(I15>=1.81,"Disagree","Strongly Disagree")))))
A16: 3 | B16: The system accurately shows my availability status to passengers. | C16: =COUNTIF('Driver Responses'!$P$6:$P$205,5) | D16: =COUNTIF('Driver Responses'!$P$6:$P$205,4) | E16: =COUNTIF('Driver Responses'!$P$6:$P$205,3) | F16: =COUNTIF('Driver Responses'!$P$6:$P$205,2) | G16: =COUNTIF('Driver Responses'!$P$6:$P$205,1) | H16: =COUNT('Driver Responses'!$P$6:$P$205) | I16: =IF(H16=0,"",(C16*5+D16*4+E16*3+F16*2+G16*1)/H16) | J16: =IF(I16="","",IF(I16>=4.21,"Strongly Agree",IF(I16>=3.41,"Agree",IF(I16>=2.61,"Neutral",IF(I16>=1.81,"Disagree","Strongly Disagree")))))
A17: 4 | B17: I can manage and track my rides through the system in real time. | C17: =COUNTIF('Driver Responses'!$Q$6:$Q$205,5) | D17: =COUNTIF('Driver Responses'!$Q$6:$Q$205,4) | E17: =COUNTIF('Driver Responses'!$Q$6:$Q$205,3) | F17: =COUNTIF('Driver Responses'!$Q$6:$Q$205,2) | G17: =COUNTIF('Driver Responses'!$Q$6:$Q$205,1) | H17: =COUNT('Driver Responses'!$Q$6:$Q$205) | I17: =IF(H17=0,"",(C17*5+D17*4+E17*3+F17*2+G17*1)/H17) | J17: =IF(I17="","",IF(I17>=4.21,"Strongly Agree",IF(I17>=3.41,"Agree",IF(I17>=2.61,"Neutral",IF(I17>=1.81,"Disagree","Strongly Disagree")))))
A18: 5 | B18: The system performs all its intended functions correctly. | C18: =COUNTIF('Driver Responses'!$R$6:$R$205,5) | D18: =COUNTIF('Driver Responses'!$R$6:$R$205,4) | E18: =COUNTIF('Driver Responses'!$R$6:$R$205,3) | F18: =COUNTIF('Driver Responses'!$R$6:$R$205,2) | G18: =COUNTIF('Driver Responses'!$R$6:$R$205,1) | H18: =COUNT('Driver Responses'!$R$6:$R$205) | I18: =IF(H18=0,"",(C18*5+D18*4+E18*3+F18*2+G18*1)/H18) | J18: =IF(I18="","",IF(I18>=4.21,"Strongly Agree",IF(I18>=3.41,"Agree",IF(I18>=2.61,"Neutral",IF(I18>=1.81,"Disagree","Strongly Disagree")))))
B19: Category mean — B. Functionality | I19: =IFERROR(AVERAGE(I14:I18),"") | J19: =IF(I19="","",IF(I19>=4.21,"Strongly Agree",IF(I19>=3.41,"Agree",IF(I19>=2.61,"Neutral",IF(I19>=1.81,"Disagree","Strongly Disagree")))))
A21: C. Efficiency
A22: 1 | B22: The system reduces my idle time waiting for passengers. | C22: =COUNTIF('Driver Responses'!$S$6:$S$205,5) | D22: =COUNTIF('Driver Responses'!$S$6:$S$205,4) | E22: =COUNTIF('Driver Responses'!$S$6:$S$205,3) | F22: =COUNTIF('Driver Responses'!$S$6:$S$205,2) | G22: =COUNTIF('Driver Responses'!$S$6:$S$205,1) | H22: =COUNT('Driver Responses'!$S$6:$S$205) | I22: =IF(H22=0,"",(C22*5+D22*4+E22*3+F22*2+G22*1)/H22) | J22: =IF(I22="","",IF(I22>=4.21,"Strongly Agree",IF(I22>=3.41,"Agree",IF(I22>=2.61,"Neutral",IF(I22>=1.81,"Disagree","Strongly Disagree")))))
A23: 2 | B23: Managing ride requests through the system is faster than the manual process. | C23: =COUNTIF('Driver Responses'!$T$6:$T$205,5) | D23: =COUNTIF('Driver Responses'!$T$6:$T$205,4) | E23: =COUNTIF('Driver Responses'!$T$6:$T$205,3) | F23: =COUNTIF('Driver Responses'!$T$6:$T$205,2) | G23: =COUNTIF('Driver Responses'!$T$6:$T$205,1) | H23: =COUNT('Driver Responses'!$T$6:$T$205) | I23: =IF(H23=0,"",(C23*5+D23*4+E23*3+F23*2+G23*1)/H23) | J23: =IF(I23="","",IF(I23>=4.21,"Strongly Agree",IF(I23>=3.41,"Agree",IF(I23>=2.61,"Neutral",IF(I23>=1.81,"Disagree","Strongly Disagree")))))
A24: 3 | B24: The system responds quickly to my inputs and actions. | C24: =COUNTIF('Driver Responses'!$U$6:$U$205,5) | D24: =COUNTIF('Driver Responses'!$U$6:$U$205,4) | E24: =COUNTIF('Driver Responses'!$U$6:$U$205,3) | F24: =COUNTIF('Driver Responses'!$U$6:$U$205,2) | G24: =COUNTIF('Driver Responses'!$U$6:$U$205,1) | H24: =COUNT('Driver Responses'!$U$6:$U$205) | I24: =IF(H24=0,"",(C24*5+D24*4+E24*3+F24*2+G24*1)/H24) | J24: =IF(I24="","",IF(I24>=4.21,"Strongly Agree",IF(I24>=3.41,"Agree",IF(I24>=2.61,"Neutral",IF(I24>=1.81,"Disagree","Strongly Disagree")))))
A25: 4 | B25: The system helps me serve more passengers throughout the day. | C25: =COUNTIF('Driver Responses'!$V$6:$V$205,5) | D25: =COUNTIF('Driver Responses'!$V$6:$V$205,4) | E25: =COUNTIF('Driver Responses'!$V$6:$V$205,3) | F25: =COUNTIF('Driver Responses'!$V$6:$V$205,2) | G25: =COUNTIF('Driver Responses'!$V$6:$V$205,1) | H25: =COUNT('Driver Responses'!$V$6:$V$205) | I25: =IF(H25=0,"",(C25*5+D25*4+E25*3+F25*2+G25*1)/H25) | J25: =IF(I25="","",IF(I25>=4.21,"Strongly Agree",IF(I25>=3.41,"Agree",IF(I25>=2.61,"Neutral",IF(I25>=1.81,"Disagree","Strongly Disagree")))))
A26: 5 | B26: Overall, the system improves my daily work experience as a driver. | C26: =COUNTIF('Driver Responses'!$W$6:$W$205,5) | D26: =COUNTIF('Driver Responses'!$W$6:$W$205,4) | E26: =COUNTIF('Driver Responses'!$W$6:$W$205,3) | F26: =COUNTIF('Driver Responses'!$W$6:$W$205,2) | G26: =COUNTIF('Driver Responses'!$W$6:$W$205,1) | H26: =COUNT('Driver Responses'!$W$6:$W$205) | I26: =IF(H26=0,"",(C26*5+D26*4+E26*3+F26*2+G26*1)/H26) | J26: =IF(I26="","",IF(I26>=4.21,"Strongly Agree",IF(I26>=3.41,"Agree",IF(I26>=2.61,"Neutral",IF(I26>=1.81,"Disagree","Strongly Disagree")))))
B27: Category mean — C. Efficiency | I27: =IFERROR(AVERAGE(I22:I26),"") | J27: =IF(I27="","",IF(I27>=4.21,"Strongly Agree",IF(I27>=3.41,"Agree",IF(I27>=2.61,"Neutral",IF(I27>=1.81,"Disagree","Strongly Disagree")))))
A29: D. Reliability
A30: 1 | B30: The system works consistently without errors or crashes. | C30: =COUNTIF('Driver Responses'!$X$6:$X$205,5) | D30: =COUNTIF('Driver Responses'!$X$6:$X$205,4) | E30: =COUNTIF('Driver Responses'!$X$6:$X$205,3) | F30: =COUNTIF('Driver Responses'!$X$6:$X$205,2) | G30: =COUNTIF('Driver Responses'!$X$6:$X$205,1) | H30: =COUNT('Driver Responses'!$X$6:$X$205) | I30: =IF(H30=0,"",(C30*5+D30*4+E30*3+F30*2+G30*1)/H30) | J30: =IF(I30="","",IF(I30>=4.21,"Strongly Agree",IF(I30>=3.41,"Agree",IF(I30>=2.61,"Neutral",IF(I30>=1.81,"Disagree","Strongly Disagree")))))
A31: 2 | B31: I can depend on the system to deliver ride requests accurately. | C31: =COUNTIF('Driver Responses'!$Y$6:$Y$205,5) | D31: =COUNTIF('Driver Responses'!$Y$6:$Y$205,4) | E31: =COUNTIF('Driver Responses'!$Y$6:$Y$205,3) | F31: =COUNTIF('Driver Responses'!$Y$6:$Y$205,2) | G31: =COUNTIF('Driver Responses'!$Y$6:$Y$205,1) | H31: =COUNT('Driver Responses'!$Y$6:$Y$205) | I31: =IF(H31=0,"",(C31*5+D31*4+E31*3+F31*2+G31*1)/H31) | J31: =IF(I31="","",IF(I31>=4.21,"Strongly Agree",IF(I31>=3.41,"Agree",IF(I31>=2.61,"Neutral",IF(I31>=1.81,"Disagree","Strongly Disagree")))))
A32: 3 | B32: The system maintains accurate and up-to-date information. | C32: =COUNTIF('Driver Responses'!$Z$6:$Z$205,5) | D32: =COUNTIF('Driver Responses'!$Z$6:$Z$205,4) | E32: =COUNTIF('Driver Responses'!$Z$6:$Z$205,3) | F32: =COUNTIF('Driver Responses'!$Z$6:$Z$205,2) | G32: =COUNTIF('Driver Responses'!$Z$6:$Z$205,1) | H32: =COUNT('Driver Responses'!$Z$6:$Z$205) | I32: =IF(H32=0,"",(C32*5+D32*4+E32*3+F32*2+G32*1)/H32) | J32: =IF(I32="","",IF(I32>=4.21,"Strongly Agree",IF(I32>=3.41,"Agree",IF(I32>=2.61,"Neutral",IF(I32>=1.81,"Disagree","Strongly Disagree")))))
A33: 4 | B33: The system performs well even during busy hours. | C33: =COUNTIF('Driver Responses'!$AA$6:$AA$205,5) | D33: =COUNTIF('Driver Responses'!$AA$6:$AA$205,4) | E33: =COUNTIF('Driver Responses'!$AA$6:$AA$205,3) | F33: =COUNTIF('Driver Responses'!$AA$6:$AA$205,2) | G33: =COUNTIF('Driver Responses'!$AA$6:$AA$205,1) | H33: =COUNT('Driver Responses'!$AA$6:$AA$205) | I33: =IF(H33=0,"",(C33*5+D33*4+E33*3+F33*2+G33*1)/H33) | J33: =IF(I33="","",IF(I33>=4.21,"Strongly Agree",IF(I33>=3.41,"Agree",IF(I33>=2.61,"Neutral",IF(I33>=1.81,"Disagree","Strongly Disagree")))))
A34: 5 | B34: I trust the system to support my work as a registered driver. | C34: =COUNTIF('Driver Responses'!$AB$6:$AB$205,5) | D34: =COUNTIF('Driver Responses'!$AB$6:$AB$205,4) | E34: =COUNTIF('Driver Responses'!$AB$6:$AB$205,3) | F34: =COUNTIF('Driver Responses'!$AB$6:$AB$205,2) | G34: =COUNTIF('Driver Responses'!$AB$6:$AB$205,1) | H34: =COUNT('Driver Responses'!$AB$6:$AB$205) | I34: =IF(H34=0,"",(C34*5+D34*4+E34*3+F34*2+G34*1)/H34) | J34: =IF(I34="","",IF(I34>=4.21,"Strongly Agree",IF(I34>=3.41,"Agree",IF(I34>=2.61,"Neutral",IF(I34>=1.81,"Disagree","Strongly Disagree")))))
B35: Category mean — D. Reliability | I35: =IFERROR(AVERAGE(I30:I34),"") | J35: =IF(I35="","",IF(I35>=4.21,"Strongly Agree",IF(I35>=3.41,"Agree",IF(I35>=2.61,"Neutral",IF(I35>=1.81,"Disagree","Strongly Disagree")))))
B37: OVERALL WEIGHTED MEAN | I37: =IFERROR(AVERAGE(I11,I19,I27,I35),"") | J37: =IF(I37="","",IF(I37>=4.21,"Strongly Agree",IF(I37>=3.41,"Agree",IF(I37>=2.61,"Neutral",IF(I37>=1.81,"Disagree","Strongly Disagree")))))
B39: The overall mean averages the category means, so each characteristic counts equally regardless of how many items it has. Average column I of the items instead if your statistician wants every item weighted equally.

Sheet Tally - Admin
A1: Tally - Admin
A2: Every figure is a formula reading 'Admin Responses' rows 6-205. Nothing on this sheet needs typing.
A4: # | B4: Indicator | C4: 5 | D4: 4 | E4: 3 | F4: 2 | G4: 1 | H4: N | I4: Weighted Mean | J4: Interpretation
A5: A. Functional Suitability
A6: 1 | B6: I can approve driver applications. | C6: =COUNTIF('Admin Responses'!$E$6:$E$205,5) | D6: =COUNTIF('Admin Responses'!$E$6:$E$205,4) | E6: =COUNTIF('Admin Responses'!$E$6:$E$205,3) | F6: =COUNTIF('Admin Responses'!$E$6:$E$205,2) | G6: =COUNTIF('Admin Responses'!$E$6:$E$205,1) | H6: =COUNT('Admin Responses'!$E$6:$E$205) | I6: =IF(H6=0,"",(C6*5+D6*4+E6*3+F6*2+G6*1)/H6) | J6: =IF(I6="","",IF(I6>=4.21,"Strongly Agree",IF(I6>=3.41,"Agree",IF(I6>=2.61,"Neutral",IF(I6>=1.81,"Disagree","Strongly Disagree")))))
A7: 2 | B7: I can monitor ride activities. | C7: =COUNTIF('Admin Responses'!$F$6:$F$205,5) | D7: =COUNTIF('Admin Responses'!$F$6:$F$205,4) | E7: =COUNTIF('Admin Responses'!$F$6:$F$205,3) | F7: =COUNTIF('Admin Responses'!$F$6:$F$205,2) | G7: =COUNTIF('Admin Responses'!$F$6:$F$205,1) | H7: =COUNT('Admin Responses'!$F$6:$F$205) | I7: =IF(H7=0,"",(C7*5+D7*4+E7*3+F7*2+G7*1)/H7) | J7: =IF(I7="","",IF(I7>=4.21,"Strongly Agree",IF(I7>=3.41,"Agree",IF(I7>=2.61,"Neutral",IF(I7>=1.81,"Disagree","Strongly Disagree")))))
A8: 3 | B8: I can manage user accounts. | C8: =COUNTIF('Admin Responses'!$G$6:$G$205,5) | D8: =COUNTIF('Admin Responses'!$G$6:$G$205,4) | E8: =COUNTIF('Admin Responses'!$G$6:$G$205,3) | F8: =COUNTIF('Admin Responses'!$G$6:$G$205,2) | G8: =COUNTIF('Admin Responses'!$G$6:$G$205,1) | H8: =COUNT('Admin Responses'!$G$6:$G$205) | I8: =IF(H8=0,"",(C8*5+D8*4+E8*3+F8*2+G8*1)/H8) | J8: =IF(I8="","",IF(I8>=4.21,"Strongly Agree",IF(I8>=3.41,"Agree",IF(I8>=2.61,"Neutral",IF(I8>=1.81,"Disagree","Strongly Disagree")))))
B9: Category mean — A. Functional Suitability | I9: =IFERROR(AVERAGE(I6:I8),"") | J9: =IF(I9="","",IF(I9>=4.21,"Strongly Agree",IF(I9>=3.41,"Agree",IF(I9>=2.61,"Neutral",IF(I9>=1.81,"Disagree","Strongly Disagree")))))
A11: B. Usability
A12: 1 | B12: The dashboard is easy to use. | C12: =COUNTIF('Admin Responses'!$H$6:$H$205,5) | D12: =COUNTIF('Admin Responses'!$H$6:$H$205,4) | E12: =COUNTIF('Admin Responses'!$H$6:$H$205,3) | F12: =COUNTIF('Admin Responses'!$H$6:$H$205,2) | G12: =COUNTIF('Admin Responses'!$H$6:$H$205,1) | H12: =COUNT('Admin Responses'!$H$6:$H$205) | I12: =IF(H12=0,"",(C12*5+D12*4+E12*3+F12*2+G12*1)/H12) | J12: =IF(I12="","",IF(I12>=4.21,"Strongly Agree",IF(I12>=3.41,"Agree",IF(I12>=2.61,"Neutral",IF(I12>=1.81,"Disagree","Strongly Disagree")))))
A13: 2 | B13: Reports are easy to generate. | C13: =COUNTIF('Admin Responses'!$I$6:$I$205,5) | D13: =COUNTIF('Admin Responses'!$I$6:$I$205,4) | E13: =COUNTIF('Admin Responses'!$I$6:$I$205,3) | F13: =COUNTIF('Admin Responses'!$I$6:$I$205,2) | G13: =COUNTIF('Admin Responses'!$I$6:$I$205,1) | H13: =COUNT('Admin Responses'!$I$6:$I$205) | I13: =IF(H13=0,"",(C13*5+D13*4+E13*3+F13*2+G13*1)/H13) | J13: =IF(I13="","",IF(I13>=4.21,"Strongly Agree",IF(I13>=3.41,"Agree",IF(I13>=2.61,"Neutral",IF(I13>=1.81,"Disagree","Strongly Disagree")))))
B14: Category mean — B. Usability | I14: =IFERROR(AVERAGE(I12:I13),"") | J14: =IF(I14="","",IF(I14>=4.21,"Strongly Agree",IF(I14>=3.41,"Agree",IF(I14>=2.61,"Neutral",IF(I14>=1.81,"Disagree","Strongly Disagree")))))
A16: C. Reliability
A17: 1 | B17: Records are accurate. | C17: =COUNTIF('Admin Responses'!$J$6:$J$205,5) | D17: =COUNTIF('Admin Responses'!$J$6:$J$205,4) | E17: =COUNTIF('Admin Responses'!$J$6:$J$205,3) | F17: =COUNTIF('Admin Responses'!$J$6:$J$205,2) | G17: =COUNTIF('Admin Responses'!$J$6:$J$205,1) | H17: =COUNT('Admin Responses'!$J$6:$J$205) | I17: =IF(H17=0,"",(C17*5+D17*4+E17*3+F17*2+G17*1)/H17) | J17: =IF(I17="","",IF(I17>=4.21,"Strongly Agree",IF(I17>=3.41,"Agree",IF(I17>=2.61,"Neutral",IF(I17>=1.81,"Disagree","Strongly Disagree")))))
A18: 2 | B18: Data updates correctly. | C18: =COUNTIF('Admin Responses'!$K$6:$K$205,5) | D18: =COUNTIF('Admin Responses'!$K$6:$K$205,4) | E18: =COUNTIF('Admin Responses'!$K$6:$K$205,3) | F18: =COUNTIF('Admin Responses'!$K$6:$K$205,2) | G18: =COUNTIF('Admin Responses'!$K$6:$K$205,1) | H18: =COUNT('Admin Responses'!$K$6:$K$205) | I18: =IF(H18=0,"",(C18*5+D18*4+E18*3+F18*2+G18*1)/H18) | J18: =IF(I18="","",IF(I18>=4.21,"Strongly Agree",IF(I18>=3.41,"Agree",IF(I18>=2.61,"Neutral",IF(I18>=1.81,"Disagree","Strongly Disagree")))))
B19: Category mean — C. Reliability | I19: =IFERROR(AVERAGE(I17:I18),"") | J19: =IF(I19="","",IF(I19>=4.21,"Strongly Agree",IF(I19>=3.41,"Agree",IF(I19>=2.61,"Neutral",IF(I19>=1.81,"Disagree","Strongly Disagree")))))
B21: OVERALL WEIGHTED MEAN | I21: =IFERROR(AVERAGE(I9,I14,I19),"") | J21: =IF(I21="","",IF(I21>=4.21,"Strongly Agree",IF(I21>=3.41,"Agree",IF(I21>=2.61,"Neutral",IF(I21>=1.81,"Disagree","Strongly Disagree")))))
B23: The overall mean averages the category means, so each characteristic counts equally regardless of how many items it has. Average column I of the items instead if your statistician wants every item weighted equally.

Sheet Open-Ended
A1: Open-Ended Responses
A2: Type the written answers verbatim, one row per respondent. Passengers answered Part IV; drivers answered Part III of their own instrument.
A4: Respondent No. | B4: Role | C4: Q1 — most useful feature | D4: Q2 — challenges or problems | E4: Q3 — features or improvements wanted | F4: Q4 — other comments
A5: EXAMPLE | B5: Passenger | C5: Seeing the fare before I book. | D5: The map was slow on mobile data. | E5: A way to save my usual destination. | F5: None.
A6: 1
A7: 2
A8: 3
A9: 4
A10: 5
A11: 6
A12: 7
A13: 8
A14: 9
A15: 10
A16: 11
A17: 12
... A205: 200
A207: The four passenger questions and the four driver questions ask the same things in the same order, so they share these columns. The Role column keeps them apart when you group the answers.
